Workbook

Sheet Test Case Summary
A1: BUSINESS & TRADE ACCOUNT — MANUAL TEST EXECUTION DASHBOARD
A2: Counts below are live formulas over the Status column of every test sheet. Set Status on each step as you go and this dashboard updates itself. A blank Status counts as Not Run.
A4: OVERALL EXECUTION
A5: Total Test Cases | B5: 231 | C5: Distinct test case IDs across all 19 test sheets.
A6: Total Test Steps | B6: =COUNTA('Business Registration'!$K$4:$K$121)+COUNTA('Business Profile'!$K$4:$K$57)+COUNTA('Trade Registration'!$K$4:$K$67)+COUNTA('Trade Approval'!$K$4:$K$64)+COUNTA('Trade Rejection'!$K$4:$K$46)+COUNTA('Trade Suspension'!$K$4:$K$42)+COUNTA('Pricing & Quantity Bands'!$K$4:$K$77)+COUNTA('Cart & Cart Repricing'!$K$4:$K$61)+COUNTA('VAT & Tax'!$K$4:$K$49)+COUNTA('Checkout'!$K$4:$K$61)+COUNTA('Payment'!$K$4:$K$48)+COUNTA('Orders'!$K$4:$K$48)+COUNTA('Invoice'!$K$4:$K$40)+COUNTA('Email Notifications'!$K$4:$K$68)+COUNTA('Admin'!$K$4:$K$55)+COUNTA('Security & Authorization'!$K$4:$K$55)+COUNTA('Mobile & Responsive'!$K$4:$K$48)+COUNTA('Regression Testing'!$K$4:$K$47)+COUNTA('End-to-End Scenarios'!$K$4:$K$80)+COUNTA('Admin Customer Preview'!$K$4:$K$162)+COUNTA('Wizard Type Switching'!$K$4:$K$97)+COUNTA('Suspended Account Access'!$K$4:$K$91) -> 1418 | C6: Individually executable steps. Each step carries its own Status.
A7: Not Run | B7: =COUNTIF('Business Registration'!$K$4:$K$121,"Not Run")+COUNTBLANK('Business Registration'!$K$4:$K$121)+COUNTIF('Business Profile'!$K$4:$K$57,"Not Run")+COUNTBLANK('Business Profile'!$K$4:$K$57)+COUNTIF('Trade Registration'!$K$4:$K$67,"Not Run")+COUNTBLANK('Trade Registration'!$K$4:$K$67)+COUNTIF('Trade Approval'!$K$4:$K$64,"Not Run")+COUNTBLANK('Trade Approval'!$K$4:$K$64)+COUNTIF('Trade Rejection'!$K$4:$K$46,"Not Run")+COUNTBLANK('Trade Rejection'!$K$4:$K$46)+COUNTIF('Trade Suspension'!$K$4:$K$42,"Not Run")+COUNTBLANK('Trade Suspension'!$K$4:$K$42)+COUNTIF('Pricing & Quantity Bands'!$K$4:$K$77,"Not Run")+COUNTBLANK('Pricing & Quantity Bands'!$K$4:$K$77)+COUNTIF('Cart & Cart Repricing'!$K$4:$K$61,"Not Run")+COUNTBLANK('Cart & Cart Repricing'!$K$4:$K$61)+COUNTIF('VAT & Tax'!$K$4:$K$49,"Not Run")+COUNTBLANK('VAT & Tax'!$K$4:$K$49)+COUNTIF('Checkout'!$K$4:$K$61,"Not Run")+COUNTBLANK('Checkout'!$K$4:$K$61)+COUNTIF('Payment'!$K$4:$K$48,"Not Run")+COUNTBLANK('Payment'!$K$4:$K$48)+COUNTIF('Orders'!$K$4:$K$48,"Not Run")+COUNTBLANK('Orders'!$K$4:$K$48)+COUNTIF('Invoice'!$K$4:$K$40,"Not Run")+COUNTBLANK('Invoice'!$K$4:$K$40)+COUNTIF('Email Notifications'!$K$4:$K$68,"Not Run")+COUNTBLANK('Email Notifications'!$K$4:$K$68)+COUNTIF('Admin'!$K$4:$K$55,"Not Run")+COUNTBLANK('Admin'!$K$4:$K$55)+COUNTIF('Security & Authorization'!$K$4:$K$55,"Not Run")+COUNTBLANK('Security & Authorization'!$K$4:$K$55)+COUNTIF('Mobile & Responsive'!$K$4:$K$48,"Not Run")+COUNTBLANK('Mobile & Responsive'!$K$4:$K$48)+COUNTIF('Regression Testing'!$K$4:$K$47,"Not Run")+COUNTBLANK('Regression Testing'!$K$4:$K$47)+COUNTIF('End-to-End Scenarios'!$K$4:$K$80,"Not Run")+COUNTBLANK('End-to-End Scenarios'!$K$4:$K$80)+COUNTIF('Admin Customer Preview'!$K$4:$K$162,"Not Run")+COUNTBLANK('Admin Customer Preview'!$K$4:$K$162)+COUNTIF('Wizard Type Switching'!$K$4:$K$97,"Not Run")+COUNTBLANK('Wizard Type Switching'!$K$4:$K$97)+COUNTIF('Suspended Account Access'!$K$4:$K$91,"Not Run")+COUNTBLANK('Suspended Account Access'!$K$4:$K$91) -> 1418 | C7: Steps not yet attempted.
A8: Passed | B8: =COUNTIF('Business Registration'!$K$4:$K$121,"Pass")+COUNTIF('Business Profile'!$K$4:$K$57,"Pass")+COUNTIF('Trade Registration'!$K$4:$K$67,"Pass")+COUNTIF('Trade Approval'!$K$4:$K$64,"Pass")+COUNTIF('Trade Rejection'!$K$4:$K$46,"Pass")+COUNTIF('Trade Suspension'!$K$4:$K$42,"Pass")+COUNTIF('Pricing & Quantity Bands'!$K$4:$K$77,"Pass")+COUNTIF('Cart & Cart Repricing'!$K$4:$K$61,"Pass")+COUNTIF('VAT & Tax'!$K$4:$K$49,"Pass")+COUNTIF('Checkout'!$K$4:$K$61,"Pass")+COUNTIF('Payment'!$K$4:$K$48,"Pass")+COUNTIF('Orders'!$K$4:$K$48,"Pass")+COUNTIF('Invoice'!$K$4:$K$40,"Pass")+COUNTIF('Email Notifications'!$K$4:$K$68,"Pass")+COUNTIF('Admin'!$K$4:$K$55,"Pass")+COUNTIF('Security & Authorization'!$K$4:$K$55,"Pass")+COUNTIF('Mobile & Responsive'!$K$4:$K$48,"Pass")+COUNTIF('Regression Testing'!$K$4:$K$47,"Pass")+COUNTIF('End-to-End Scenarios'!$K$4:$K$80,"Pass")+COUNTIF('Admin Customer Preview'!$K$4:$K$162,"Pass")+COUNTIF('Wizard Type Switching'!$K$4:$K$97,"Pass")+COUNTIF('Suspended Account Access'!$K$4:$K$91,"Pass") -> 0 | C8: Steps where actual behaviour matched the expected result.
A9: Failed | B9: =COUNTIF('Business Registration'!$K$4:$K$121,"Fail")+COUNTIF('Business Profile'!$K$4:$K$57,"Fail")+COUNTIF('Trade Registration'!$K$4:$K$67,"Fail")+COUNTIF('Trade Approval'!$K$4:$K$64,"Fail")+COUNTIF('Trade Rejection'!$K$4:$K$46,"Fail")+COUNTIF('Trade Suspension'!$K$4:$K$42,"Fail")+COUNTIF('Pricing & Quantity Bands'!$K$4:$K$77,"Fail")+COUNTIF('Cart & Cart Repricing'!$K$4:$K$61,"Fail")+COUNTIF('VAT & Tax'!$K$4:$K$49,"Fail")+COUNTIF('Checkout'!$K$4:$K$61,"Fail")+COUNTIF('Payment'!$K$4:$K$48,"Fail")+COUNTIF('Orders'!$K$4:$K$48,"Fail")+COUNTIF('Invoice'!$K$4:$K$40,"Fail")+COUNTIF('Email Notifications'!$K$4:$K$68,"Fail")+COUNTIF('Admin'!$K$4:$K$55,"Fail")+COUNTIF('Security & Authorization'!$K$4:$K$55,"Fail")+COUNTIF('Mobile & Responsive'!$K$4:$K$48,"Fail")+COUNTIF('Regression Testing'!$K$4:$K$47,"Fail")+COUNTIF('End-to-End Scenarios'!$K$4:$K$80,"Fail")+COUNTIF('Admin Customer Preview'!$K$4:$K$162,"Fail")+COUNTIF('Wizard Type Switching'!$K$4:$K$97,"Fail")+COUNTIF('Suspended Account Access'!$K$4:$K$91,"Fail") -> 0 | C9: Steps where actual behaviour differed. Raise a defect for each.
A10: Blocked | B10: =COUNTIF('Business Registration'!$K$4:$K$121,"Blocked")+COUNTIF('Business Profile'!$K$4:$K$57,"Blocked")+COUNTIF('Trade Registration'!$K$4:$K$67,"Blocked")+COUNTIF('Trade Approval'!$K$4:$K$64,"Blocked")+COUNTIF('Trade Rejection'!$K$4:$K$46,"Blocked")+COUNTIF('Trade Suspension'!$K$4:$K$42,"Blocked")+COUNTIF('Pricing & Quantity Bands'!$K$4:$K$77,"Blocked")+COUNTIF('Cart & Cart Repricing'!$K$4:$K$61,"Blocked")+COUNTIF('VAT & Tax'!$K$4:$K$49,"Blocked")+COUNTIF('Checkout'!$K$4:$K$61,"Blocked")+COUNTIF('Payment'!$K$4:$K$48,"Blocked")+COUNTIF('Orders'!$K$4:$K$48,"Blocked")+COUNTIF('Invoice'!$K$4:$K$40,"Blocked")+COUNTIF('Email Notifications'!$K$4:$K$68,"Blocked")+COUNTIF('Admin'!$K$4:$K$55,"Blocked")+COUNTIF('Security & Authorization'!$K$4:$K$55,"Blocked")+COUNTIF('Mobile & Responsive'!$K$4:$K$48,"Blocked")+COUNTIF('Regression Testing'!$K$4:$K$47,"Blocked")+COUNTIF('End-to-End Scenarios'!$K$4:$K$80,"Blocked")+COUNTIF('Admin Customer Preview'!$K$4:$K$162,"Blocked")+COUNTIF('Wizard Type Switching'!$K$4:$K$97,"Blocked")+COUNTIF('Suspended Account Access'!$K$4:$K$91,"Blocked") -> 0 | C10: Could not be executed (environment, data or an earlier failure).
A11: Not Applicable | B11: =COUNTIF('Business Registration'!$K$4:$K$121,"Not Applicable")+COUNTIF('Business Profile'!$K$4:$K$57,"Not Applicable")+COUNTIF('Trade Registration'!$K$4:$K$67,"Not Applicable")+COUNTIF('Trade Approval'!$K$4:$K$64,"Not Applicable")+COUNTIF('Trade Rejection'!$K$4:$K$46,"Not Applicable")+COUNTIF('Trade Suspension'!$K$4:$K$42,"Not Applicable")+COUNTIF('Pricing & Quantity Bands'!$K$4:$K$77,"Not Applicable")+COUNTIF('Cart & Cart Repricing'!$K$4:$K$61,"Not Applicable")+COUNTIF('VAT & Tax'!$K$4:$K$49,"Not Applicable")+COUNTIF('Checkout'!$K$4:$K$61,"Not Applicable")+COUNTIF('Payment'!$K$4:$K$48,"Not Applicable")+COUNTIF('Orders'!$K$4:$K$48,"Not Applicable")+COUNTIF('Invoice'!$K$4:$K$40,"Not Applicable")+COUNTIF('Email Notifications'!$K$4:$K$68,"Not Applicable")+COUNTIF('Admin'!$K$4:$K$55,"Not Applicable")+COUNTIF('Security & Authorization'!$K$4:$K$55,"Not Applicable")+COUNTIF('Mobile & Responsive'!$K$4:$K$48,"Not Applicable")+COUNTIF('Regression Testing'!$K$4:$K$47,"Not Applicable")+COUNTIF('End-to-End Scenarios'!$K$4:$K$80,"Not Applicable")+COUNTIF('Admin Customer Preview'!$K$4:$K$162,"Not Applicable")+COUNTIF('Wizard Type Switching'!$K$4:$K$97,"Not Applicable")+COUNTIF('Suspended Account Access'!$K$4:$K$91,"Not Applicable") -> 0 | C11: Feature not implemented in this build. NOT a failure.
A12: Pass Rate (of executed) | B12: =IF((B8+B9)=0,"—",B8/(B8+B9)) -> — | C12: Passed / (Passed + Failed). Blocked and Not Applicable steps are excluded.
A14: FAILURES BY SEVERITY
A15: Critical Failures | B15: =_xlfn.COUNTIFS('Business Registration'!$K$4:$K$121,"Fail",'Business Registration'!$L$4:$L$121,"Critical")+_xlfn.COUNTIFS('Business Profile'!$K$4:$K$57,"Fail",'Business Profile'!$L$4:$L$57,"Critical")+_xlfn.COUNTIFS('Trade Registration'!$K$4:$K$67,"Fail",'Trade Registration'!$L$4:$L$67,"Critical")+_xlfn.COUNTIFS('Trade Approval'!$K$4:$K$64,"Fail",'Trade Approval'!$L$4:$L$64,"Critical")+_xlfn.COUNTIFS('Trade Rejection'!$K$4:$K$46,"Fail",'Trade Rejection'!$L$4:$L$46,"Critical")+_xlfn.COUNTIFS('Trade Suspension'!$K$4:$K$42,"Fail",'Trade Suspension'!$L$4:$L$42,"Critical")+_xlfn.COUNTIFS('Pricing & Quantity Bands'!$K$4:$K$77,"Fail",'Pricing & Quantity Bands'!$L$4:$L$77,"Critical")+_xlfn.COUNTIFS('Cart & Cart Repricing'!$K$4:$K$61,"Fail",'Cart & Cart Repricing'!$L$4:$L$61,"Critical")+_xlfn.COUNTIFS('VAT & Tax'!$K$4:$K$49,"Fail",'VAT & Tax'!$L$4:$L$49,"Critical")+_xlfn.COUNTIFS('Checkout'!$K$4:$K$61,"Fail",'Checkout'!$L$4:$L$61,"Critical")+_xlfn.COUNTIFS('Payment'!$K$4:$K$48,"Fail",'Payment'!$L$4:$L$48,"Critical")+_xlfn.COUNTIFS('Orders'!$K$4:$K$48,"Fail",'Orders'!$L$4:$L$48,"Critical")+_xlfn.COUNTIFS('Invoice'!$K$4:$K$40,"Fail",'Invoice'!$L$4:$L$40,"Critical")+_xlfn.COUNTIFS('Email Notifications'!$K$4:$K$68,"Fail",'Email Notifications'!$L$4:$L$68,"Critical")+_xlfn.COUNTIFS('Admin'!$K$4:$K$55,"Fail",'Admin'!$L$4:$L$55,"Critical")+_xlfn.COUNTIFS('Security & Authorization'!$K$4:$K$55,"Fail",'Security & Authorization'!$L$4:$L$55,"Critical")+_xlfn.COUNTIFS('Mobile & Responsive'!$K$4:$K$48,"Fail",'Mobile & Responsive'!$L$4:$L$48,"Critical")+_xlfn.COUNTIFS('Regression Testing'!$K$4:$K$47,"Fail",'Regression Testing'!$L$4:$L$47,"Critical")+_xlfn.COUNTIFS('End-to-End Scenarios'!$K$4:$K$80,"Fail",'End-to-End Scenarios'!$L$4:$L$80,"Critical")+_xlfn.COUNTIFS('Admin Customer Preview'!$K$4:$K$162,"Fail",'Admin Customer Preview'!$L$4:$L$162,"Critical")+_xlfn.COUNTIFS('Wizard Type Switching'!$K$4:$K$97,"Fail",'Wizard Type Switching'!$L$4:$L$97,"Critical")+_xlfn.COUNTIFS('Suspended Account Access'!$K$4:$K$91,"Fail",'Suspended Account Access'!$L$4:$L$91,"Critical") -> 0 | C15: Blocks release. Business/trade cannot transact, or money/permissions are wrong.
A16: Major Failures | B16: =_xlfn.COUNTIFS('Business Registration'!$K$4:$K$121,"Fail",'Business Registration'!$L$4:$L$121,"Major")+_xlfn.COUNTIFS('Business Profile'!$K$4:$K$57,"Fail",'Business Profile'!$L$4:$L$57,"Major")+_xlfn.COUNTIFS('Trade Registration'!$K$4:$K$67,"Fail",'Trade Registration'!$L$4:$L$67,"Major")+_xlfn.COUNTIFS('Trade Approval'!$K$4:$K$64,"Fail",'Trade Approval'!$L$4:$L$64,"Major")+_xlfn.COUNTIFS('Trade Rejection'!$K$4:$K$46,"Fail",'Trade Rejection'!$L$4:$L$46,"Major")+_xlfn.COUNTIFS('Trade Suspension'!$K$4:$K$42,"Fail",'Trade Suspension'!$L$4:$L$42,"Major")+_xlfn.COUNTIFS('Pricing & Quantity Bands'!$K$4:$K$77,"Fail",'Pricing & Quantity Bands'!$L$4:$L$77,"Major")+_xlfn.COUNTIFS('Cart & Cart Repricing'!$K$4:$K$61,"Fail",'Cart & Cart Repricing'!$L$4:$L$61,"Major")+_xlfn.COUNTIFS('VAT & Tax'!$K$4:$K$49,"Fail",'VAT & Tax'!$L$4:$L$49,"Major")+_xlfn.COUNTIFS('Checkout'!$K$4:$K$61,"Fail",'Checkout'!$L$4:$L$61,"Major")+_xlfn.COUNTIFS('Payment'!$K$4:$K$48,"Fail",'Payment'!$L$4:$L$48,"Major")+_xlfn.COUNTIFS('Orders'!$K$4:$K$48,"Fail",'Orders'!$L$4:$L$48,"Major")+_xlfn.COUNTIFS('Invoice'!$K$4:$K$40,"Fail",'Invoice'!$L$4:$L$40,"Major")+_xlfn.COUNTIFS('Email Notifications'!$K$4:$K$68,"Fail",'Email Notifications'!$L$4:$L$68,"Major")+_xlfn.COUNTIFS('Admin'!$K$4:$K$55,"Fail",'Admin'!$L$4:$L$55,"Major")+_xlfn.COUNTIFS('Security & Authorization'!$K$4:$K$55,"Fail",'Security & Authorization'!$L$4:$L$55,"Major")+_xlfn.COUNTIFS('Mobile & Responsive'!$K$4:$K$48,"Fail",'Mobile & Responsive'!$L$4:$L$48,"Major")+_xlfn.COUNTIFS('Regression Testing'!$K$4:$K$47,"Fail",'Regression Testing'!$L$4:$L$47,"Major")+_xlfn.COUNTIFS('End-to-End Scenarios'!$K$4:$K$80,"Fail",'End-to-End Scenarios'!$L$4:$L$80,"Major")+_xlfn.COUNTIFS('Admin Customer Preview'!$K$4:$K$162,"Fail",'Admin Customer Preview'!$L$4:$L$162,"Major")+_xlfn.COUNTIFS('Wizard Type Switching'!$K$4:$K$97,"Fail",'Wizard Type Switching'!$L$4:$L$97,"Major")+_xlfn.COUNTIFS('Suspended Account Access'!$K$4:$K$91,"Fail",'Suspended Account Access'!$L$4:$L$91,"Major") -> 0 | C16: Core function broken with no workaround.
A17: Minor Failures | B17: =_xlfn.COUNTIFS('Business Registration'!$K$4:$K$121,"Fail",'Business Registration'!$L$4:$L$121,"Minor")+_xlfn.COUNTIFS('Business Profile'!$K$4:$K$57,"Fail",'Business Profile'!$L$4:$L$57,"Minor")+_xlfn.COUNTIFS('Trade Registration'!$K$4:$K$67,"Fail",'Trade Registration'!$L$4:$L$67,"Minor")+_xlfn.COUNTIFS('Trade Approval'!$K$4:$K$64,"Fail",'Trade Approval'!$L$4:$L$64,"Minor")+_xlfn.COUNTIFS('Trade Rejection'!$K$4:$K$46,"Fail",'Trade Rejection'!$L$4:$L$46,"Minor")+_xlfn.COUNTIFS('Trade Suspension'!$K$4:$K$42,"Fail",'Trade Suspension'!$L$4:$L$42,"Minor")+_xlfn.COUNTIFS('Pricing & Quantity Bands'!$K$4:$K$77,"Fail",'Pricing & Quantity Bands'!$L$4:$L$77,"Minor")+_xlfn.COUNTIFS('Cart & Cart Repricing'!$K$4:$K$61,"Fail",'Cart & Cart Repricing'!$L$4:$L$61,"Minor")+_xlfn.COUNTIFS('VAT & Tax'!$K$4:$K$49,"Fail",'VAT & Tax'!$L$4:$L$49,"Minor")+_xlfn.COUNTIFS('Checkout'!$K$4:$K$61,"Fail",'Checkout'!$L$4:$L$61,"Minor")+_xlfn.COUNTIFS('Payment'!$K$4:$K$48,"Fail",'Payment'!$L$4:$L$48,"Minor")+_xlfn.COUNTIFS('Orders'!$K$4:$K$48,"Fail",'Orders'!$L$4:$L$48,"Minor")+_xlfn.COUNTIFS('Invoice'!$K$4:$K$40,"Fail",'Invoice'!$L$4:$L$40,"Minor")+_xlfn.COUNTIFS('Email Notifications'!$K$4:$K$68,"Fail",'Email Notifications'!$L$4:$L$68,"Minor")+_xlfn.COUNTIFS('Admin'!$K$4:$K$55,"Fail",'Admin'!$L$4:$L$55,"Minor")+_xlfn.COUNTIFS('Security & Authorization'!$K$4:$K$55,"Fail",'Security & Authorization'!$L$4:$L$55,"Minor")+_xlfn.COUNTIFS('Mobile & Responsive'!$K$4:$K$48,"Fail",'Mobile & Responsive'!$L$4:$L$48,"Minor")+_xlfn.COUNTIFS('Regression Testing'!$K$4:$K$47,"Fail",'Regression Testing'!$L$4:$L$47,"Minor")+_xlfn.COUNTIFS('End-to-End Scenarios'!$K$4:$K$80,"Fail",'End-to-End Scenarios'!$L$4:$L$80,"Minor")+_xlfn.COUNTIFS('Admin Customer Preview'!$K$4:$K$162,"Fail",'Admin Customer Preview'!$L$4:$L$162,"Minor")+_xlfn.COUNTIFS('Wizard Type Switching'!$K$4:$K$97,"Fail",'Wizard Type Switching'!$L$4:$L$97,"Minor")+_xlfn.COUNTIFS('Suspended Account Access'!$K$4:$K$91,"Fail",'Suspended Account Access'!$L$4:$L$91,"Minor") -> 0 | C17: Function works with a workaround, or a small data/display error.
A18: Cosmetic Failures | B18: =_xlfn.COUNTIFS('Business Registration'!$K$4:$K$121,"Fail",'Business Registration'!$L$4:$L$121,"Cosmetic")+_xlfn.COUNTIFS('Business Profile'!$K$4:$K$57,"Fail",'Business Profile'!$L$4:$L$57,"Cosmetic")+_xlfn.COUNTIFS('Trade Registration'!$K$4:$K$67,"Fail",'Trade Registration'!$L$4:$L$67,"Cosmetic")+_xlfn.COUNTIFS('Trade Approval'!$K$4:$K$64,"Fail",'Trade Approval'!$L$4:$L$64,"Cosmetic")+_xlfn.COUNTIFS('Trade Rejection'!$K$4:$K$46,"Fail",'Trade Rejection'!$L$4:$L$46,"Cosmetic")+_xlfn.COUNTIFS('Trade Suspension'!$K$4:$K$42,"Fail",'Trade Suspension'!$L$4:$L$42,"Cosmetic")+_xlfn.COUNTIFS('Pricing & Quantity Bands'!$K$4:$K$77,"Fail",'Pricing & Quantity Bands'!$L$4:$L$77,"Cosmetic")+_xlfn.COUNTIFS('Cart & Cart Repricing'!$K$4:$K$61,"Fail",'Cart & Cart Repricing'!$L$4:$L$61,"Cosmetic")+_xlfn.COUNTIFS('VAT & Tax'!$K$4:$K$49,"Fail",'VAT & Tax'!$L$4:$L$49,"Cosmetic")+_xlfn.COUNTIFS('Checkout'!$K$4:$K$61,"Fail",'Checkout'!$L$4:$L$61,"Cosmetic")+_xlfn.COUNTIFS('Payment'!$K$4:$K$48,"Fail",'Payment'!$L$4:$L$48,"Cosmetic")+_xlfn.COUNTIFS('Orders'!$K$4:$K$48,"Fail",'Orders'!$L$4:$L$48,"Cosmetic")+_xlfn.COUNTIFS('Invoice'!$K$4:$K$40,"Fail",'Invoice'!$L$4:$L$40,"Cosmetic")+_xlfn.COUNTIFS('Email Notifications'!$K$4:$K$68,"Fail",'Email Notifications'!$L$4:$L$68,"Cosmetic")+_xlfn.COUNTIFS('Admin'!$K$4:$K$55,"Fail",'Admin'!$L$4:$L$55,"Cosmetic")+_xlfn.COUNTIFS('Security & Authorization'!$K$4:$K$55,"Fail",'Security & Authorization'!$L$4:$L$55,"Cosmetic")+_xlfn.COUNTIFS('Mobile & Responsive'!$K$4:$K$48,"Fail",'Mobile & Responsive'!$L$4:$L$48,"Cosmetic")+_xlfn.COUNTIFS('Regression Testing'!$K$4:$K$47,"Fail",'Regression Testing'!$L$4:$L$47,"Cosmetic")+_xlfn.COUNTIFS('End-to-End Scenarios'!$K$4:$K$80,"Fail",'End-to-End Scenarios'!$L$4:$L$80,"Cosmetic")+_xlfn.COUNTIFS('Admin Customer Preview'!$K$4:$K$162,"Fail",'Admin Customer Preview'!$L$4:$L$162,"Cosmetic")+_xlfn.COUNTIFS('Wizard Type Switching'!$K$4:$K$97,"Fail",'Wizard Type Switching'!$L$4:$L$97,"Cosmetic")+_xlfn.COUNTIFS('Suspended Account Access'!$K$4:$K$91,"Fail",'Suspended Account Access'!$L$4:$L$91,"Cosmetic") -> 0 | C18: Visual or wording only; no functional impact.
A19: Failures with no Severity set | B19: =_xlfn.COUNTIFS('Business Registration'!$K$4:$K$121,"Fail",'Business Registration'!$L$4:$L$121,"")+_xlfn.COUNTIFS('Business Profile'!$K$4:$K$57,"Fail",'Business Profile'!$L$4:$L$57,"")+_xlfn.COUNTIFS('Trade Registration'!$K$4:$K$67,"Fail",'Trade Registration'!$L$4:$L$67,"")+_xlfn.COUNTIFS('Trade Approval'!$K$4:$K$64,"Fail",'Trade Approval'!$L$4:$L$64,"")+_xlfn.COUNTIFS('Trade Rejection'!$K$4:$K$46,"Fail",'Trade Rejection'!$L$4:$L$46,"")+_xlfn.COUNTIFS('Trade Suspension'!$K$4:$K$42,"Fail",'Trade Suspension'!$L$4:$L$42,"")+_xlfn.COUNTIFS('Pricing & Quantity Bands'!$K$4:$K$77,"Fail",'Pricing & Quantity Bands'!$L$4:$L$77,"")+_xlfn.COUNTIFS('Cart & Cart Repricing'!$K$4:$K$61,"Fail",'Cart & Cart Repricing'!$L$4:$L$61,"")+_xlfn.COUNTIFS('VAT & Tax'!$K$4:$K$49,"Fail",'VAT & Tax'!$L$4:$L$49,"")+_xlfn.COUNTIFS('Checkout'!$K$4:$K$61,"Fail",'Checkout'!$L$4:$L$61,"")+_xlfn.COUNTIFS('Payment'!$K$4:$K$48,"Fail",'Payment'!$L$4:$L$48,"")+_xlfn.COUNTIFS('Orders'!$K$4:$K$48,"Fail",'Orders'!$L$4:$L$48,"")+_xlfn.COUNTIFS('Invoice'!$K$4:$K$40,"Fail",'Invoice'!$L$4:$L$40,"")+_xlfn.COUNTIFS('Email Notifications'!$K$4:$K$68,"Fail",'Email Notifications'!$L$4:$L$68,"")+_xlfn.COUNTIFS('Admin'!$K$4:$K$55,"Fail",'Admin'!$L$4:$L$55,"")+_xlfn.COUNTIFS('Security & Authorization'!$K$4:$K$55,"Fail",'Security & Authorization'!$L$4:$L$55,"")+_xlfn.COUNTIFS('Mobile & Responsive'!$K$4:$K$48,"Fail",'Mobile & Responsive'!$L$4:$L$48,"")+_xlfn.COUNTIFS('Regression Testing'!$K$4:$K$47,"Fail",'Regression Testing'!$L$4:$L$47,"")+_xlfn.COUNTIFS('End-to-End Scenarios'!$K$4:$K$80,"Fail",'End-to-End Scenarios'!$L$4:$L$80,"")+_xlfn.COUNTIFS('Admin Customer Preview'!$K$4:$K$162,"Fail",'Admin Customer Preview'!$L$4:$L$162,"")+_xlfn.COUNTIFS('Wizard Type Switching'!$K$4:$K$97,"Fail",'Wizard Type Switching'!$L$4:$L$97,"")+_xlfn.COUNTIFS('Suspended Account Access'!$K$4:$K$91,"Fail",'Suspended Account Access'!$L$4:$L$91,"") -> 0 | C19: Set a Severity on every failed step, or it will not appear in the counts above.
A21: MODULE-WISE BREAKDOWN — EXECUTE IN THIS ORDER (top to bottom)
A22: Module / Sheet (execute in this order) | B22: Cases | C22: Steps | D22: Not Run | E22: Pass | F22: Fail | G22: Blocked | H22: N/A
A23: 1. Business Registration | B23: 20 | C23: =COUNTA('Business Registration'!$K$4:$K$121) -> 118 | D23: =COUNTIF('Business Registration'!$K$4:$K$121,"Not Run")+COUNTBLANK('Business Registration'!$K$4:$K$121) -> 118 | E23: =COUNTIF('Business Registration'!$K$4:$K$121,"Pass") -> 0 | F23: =COUNTIF('Business Registration'!$K$4:$K$121,"Fail") -> 0 | G23: =COUNTIF('Business Registration'!$K$4:$K$121,"Blocked") -> 0 | H23: =COUNTIF('Business Registration'!$K$4:$K$121,"Not Applicable") -> 0
A24: 2. Business Profile | B24: 10 | C24: =COUNTA('Business Profile'!$K$4:$K$57) -> 54 | D24: =COUNTIF('Business Profile'!$K$4:$K$57,"Not Run")+COUNTBLANK('Business Profile'!$K$4:$K$57) -> 54 | E24: =COUNTIF('Business Profile'!$K$4:$K$57,"Pass") -> 0 | F24: =COUNTIF('Business Profile'!$K$4:$K$57,"Fail") -> 0 | G24: =COUNTIF('Business Profile'!$K$4:$K$57,"Blocked") -> 0 | H24: =COUNTIF('Business Profile'!$K$4:$K$57,"Not Applicable") -> 0
A25: 3. Trade Registration | B25: 10 | C25: =COUNTA('Trade Registration'!$K$4:$K$67) -> 64 | D25: =COUNTIF('Trade Registration'!$K$4:$K$67,"Not Run")+COUNTBLANK('Trade Registration'!$K$4:$K$67) -> 64 | E25: =COUNTIF('Trade Registration'!$K$4:$K$67,"Pass") -> 0 | F25: =COUNTIF('Trade Registration'!$K$4:$K$67,"Fail") -> 0 | G25: =COUNTIF('Trade Registration'!$K$4:$K$67,"Blocked") -> 0 | H25: =COUNTIF('Trade Registration'!$K$4:$K$67,"Not Applicable") -> 0
A26: 4. Trade Approval | B26: 10 | C26: =COUNTA('Trade Approval'!$K$4:$K$64) -> 61 | D26: =COUNTIF('Trade Approval'!$K$4:$K$64,"Not Run")+COUNTBLANK('Trade Approval'!$K$4:$K$64) -> 61 | E26: =COUNTIF('Trade Approval'!$K$4:$K$64,"Pass") -> 0 | F26: =COUNTIF('Trade Approval'!$K$4:$K$64,"Fail") -> 0 | G26: =COUNTIF('Trade Approval'!$K$4:$K$64,"Blocked") -> 0 | H26: =COUNTIF('Trade Approval'!$K$4:$K$64,"Not Applicable") -> 0
A27: 5. Trade Rejection | B27: 8 | C27: =COUNTA('Trade Rejection'!$K$4:$K$46) -> 43 | D27: =COUNTIF('Trade Rejection'!$K$4:$K$46,"Not Run")+COUNTBLANK('Trade Rejection'!$K$4:$K$46) -> 43 | E27: =COUNTIF('Trade Rejection'!$K$4:$K$46,"Pass") -> 0 | F27: =COUNTIF('Trade Rejection'!$K$4:$K$46,"Fail") -> 0 | G27: =COUNTIF('Trade Rejection'!$K$4:$K$46,"Blocked") -> 0 | H27: =COUNTIF('Trade Rejection'!$K$4:$K$46,"Not Applicable") -> 0
A28: 6. Trade Suspension | B28: 7 | C28: =COUNTA('Trade Suspension'!$K$4:$K$42) -> 39 | D28: =COUNTIF('Trade Suspension'!$K$4:$K$42,"Not Run")+COUNTBLANK('Trade Suspension'!$K$4:$K$42) -> 39 | E28: =COUNTIF('Trade Suspension'!$K$4:$K$42,"Pass") -> 0 | F28: =COUNTIF('Trade Suspension'!$K$4:$K$42,"Fail") -> 0 | G28: =COUNTIF('Trade Suspension'!$K$4:$K$42,"Blocked") -> 0 | H28: =COUNTIF('Trade Suspension'!$K$4:$K$42,"Not Applicable") -> 0
A29: 7. Pricing & Quantity Bands | B29: 14 | C29: =COUNTA('Pricing & Quantity Bands'!$K$4:$K$77) -> 74 | D29: =COUNTIF('Pricing & Quantity Bands'!$K$4:$K$77,"Not Run")+COUNTBLANK('Pricing & Quantity Bands'!$K$4:$K$77) -> 74 | E29: =COUNTIF('Pricing & Quantity Bands'!$K$4:$K$77,"Pass") -> 0 | F29: =COUNTIF('Pricing & Quantity Bands'!$K$4:$K$77,"Fail") -> 0 | G29: =COUNTIF('Pricing & Quantity Bands'!$K$4:$K$77,"Blocked") -> 0 | H29: =COUNTIF('Pricing & Quantity Bands'!$K$4:$K$77,"Not Applicable") -> 0
A30: 8. Cart & Cart Repricing | B30: 11 | C30: =COUNTA('Cart & Cart Repricing'!$K$4:$K$61) -> 58 | D30: =COUNTIF('Cart & Cart Repricing'!$K$4:$K$61,"Not Run")+COUNTBLANK('Cart & Cart Repricing'!$K$4:$K$61) -> 58 | E30: =COUNTIF('Cart & Cart Repricing'!$K$4:$K$61,"Pass") -> 0 | F30: =COUNTIF('Cart & Cart Repricing'!$K$4:$K$61,"Fail") -> 0 | G30: =COUNTIF('Cart & Cart Repricing'!$K$4:$K$61,"Blocked") -> 0 | H30: =COUNTIF('Cart & Cart Repricing'!$K$4:$K$61,"Not Applicable") -> 0
A31: 9. VAT & Tax | B31: 9 | C31: =COUNTA('VAT & Tax'!$K$4:$K$49) -> 46 | D31: =COUNTIF('VAT & Tax'!$K$4:$K$49,"Not Run")+COUNTBLANK('VAT & Tax'!$K$4:$K$49) -> 46 | E31: =COUNTIF('VAT & Tax'!$K$4:$K$49,"Pass") -> 0 | F31: =COUNTIF('VAT & Tax'!$K$4:$K$49,"Fail") -> 0 | G31: =COUNTIF('VAT & Tax'!$K$4:$K$49,"Blocked") -> 0 | H31: =COUNTIF('VAT & Tax'!$K$4:$K$49,"Not Applicable") -> 0
A32: 10. Checkout | B32: 10 | C32: =COUNTA('Checkout'!$K$4:$K$61) -> 58 | D32: =COUNTIF('Checkout'!$K$4:$K$61,"Not Run")+COUNTBLANK('Checkout'!$K$4:$K$61) -> 58 | E32: =COUNTIF('Checkout'!$K$4:$K$61,"Pass") -> 0 | F32: =COUNTIF('Checkout'!$K$4:$K$61,"Fail") -> 0 | G32: =COUNTIF('Checkout'!$K$4:$K$61,"Blocked") -> 0 | H32: =COUNTIF('Checkout'!$K$4:$K$61,"Not Applicable") -> 0
A33: 11. Payment | B33: 9 | C33: =COUNTA('Payment'!$K$4:$K$48) -> 45 | D33: =COUNTIF('Payment'!$K$4:$K$48,"Not Run")+COUNTBLANK('Payment'!$K$4:$K$48) -> 45 | E33: =COUNTIF('Payment'!$K$4:$K$48,"Pass") -> 0 | F33: =COUNTIF('Payment'!$K$4:$K$48,"Fail") -> 0 | G33: =COUNTIF('Payment'!$K$4:$K$48,"Blocked") -> 0 | H33: =COUNTIF('Payment'!$K$4:$K$48,"Not Applicable") -> 0
A34: 12. Orders | B34: 7 | C34: =COUNTA('Orders'!$K$4:$K$48) -> 45 | D34: =COUNTIF('Orders'!$K$4:$K$48,"Not Run")+COUNTBLANK('Orders'!$K$4:$K$48) -> 45 | E34: =COUNTIF('Orders'!$K$4:$K$48,"Pass") -> 0 | F34: =COUNTIF('Orders'!$K$4:$K$48,"Fail") -> 0 | G34: =COUNTIF('Orders'!$K$4:$K$48,"Blocked") -> 0 | H34: =COUNTIF('Orders'!$K$4:$K$48,"Not Applicable") -> 0
A35: 13. Invoice | B35: 6 | C35: =COUNTA('Invoice'!$K$4:$K$40) -> 37 | D35: =COUNTIF('Invoice'!$K$4:$K$40,"Not Run")+COUNTBLANK('Invoice'!$K$4:$K$40) -> 37 | E35: =COUNTIF('Invoice'!$K$4:$K$40,"Pass") -> 0 | F35: =COUNTIF('Invoice'!$K$4:$K$40,"Fail") -> 0 | G35: =COUNTIF('Invoice'!$K$4:$K$40,"Blocked") -> 0 | H35: =COUNTIF('Invoice'!$K$4:$K$40,"Not Applicable") -> 0
A36: 14. Email Notifications | B36: 13 | C36: =COUNTA('Email Notifications'!$K$4:$K$68) -> 65 | D36: =COUNTIF('Email Notifications'!$K$4:$K$68,"Not Run")+COUNTBLANK('Email Notifications'!$K$4:$K$68) -> 65 | E36: =COUNTIF('Email Notifications'!$K$4:$K$68,"Pass") -> 0 | F36: =COUNTIF('Email Notifications'!$K$4:$K$68,"Fail") -> 0 | G36: =COUNTIF('Email Notifications'!$K$4:$K$68,"Blocked") -> 0 | H36: =COUNTIF('Email Notifications'!$K$4:$K$68,"Not Applicable") -> 0
A37: 15. Admin | B37: 8 | C37: =COUNTA('Admin'!$K$4:$K$55) -> 52 | D37: =COUNTIF('Admin'!$K$4:$K$55,"Not Run")+COUNTBLANK('Admin'!$K$4:$K$55) -> 52 | E37: =COUNTIF('Admin'!$K$4:$K$55,"Pass") -> 0 | F37: =COUNTIF('Admin'!$K$4:$K$55,"Fail") -> 0 | G37: =COUNTIF('Admin'!$K$4:$K$55,"Blocked") -> 0 | H37: =COUNTIF('Admin'!$K$4:$K$55,"Not Applicable") -> 0
A38: 16. Security & Authorization | B38: 9 | C38: =COUNTA('Security & Authorization'!$K$4:$K$55) -> 52 | D38: =COUNTIF('Security & Authorization'!$K$4:$K$55,"Not Run")+COUNTBLANK('Security & Authorization'!$K$4:$K$55) -> 52 | E38: =COUNTIF('Security & Authorization'!$K$4:$K$55,"Pass") -> 0 | F38: =COUNTIF('Security & Authorization'!$K$4:$K$55,"Fail") -> 0 | G38: =COUNTIF('Security & Authorization'!$K$4:$K$55,"Blocked") -> 0 | H38: =COUNTIF('Security & Authorization'!$K$4:$K$55,"Not Applicable") -> 0
A39: 17. Mobile & Responsive | B39: 8 | C39: =COUNTA('Mobile & Responsive'!$K$4:$K$48) -> 45 | D39: =COUNTIF('Mobile & Responsive'!$K$4:$K$48,"Not Run")+COUNTBLANK('Mobile & Responsive'!$K$4:$K$48) -> 45 | E39: =COUNTIF('Mobile & Responsive'!$K$4:$K$48,"Pass") -> 0 | F39: =COUNTIF('Mobile & Responsive'!$K$4:$K$48,"Fail") -> 0 | G39: =COUNTIF('Mobile & Responsive'!$K$4:$K$48,"Blocked") -> 0 | H39: =COUNTIF('Mobile & Responsive'!$K$4:$K$48,"Not Applicable") -> 0
A40: 18. Regression Testing | B40: 8 | C40: =COUNTA('Regression Testing'!$K$4:$K$47) -> 44 | D40: =COUNTIF('Regression Testing'!$K$4:$K$47,"Not Run")+COUNTBLANK('Regression Testing'!$K$4:$K$47) -> 44 | E40: =COUNTIF('Regression Testing'!$K$4:$K$47,"Pass") -> 0 | F40: =COUNTIF('Regression Testing'!$K$4:$K$47,"Fail") -> 0 | G40: =COUNTIF('Regression Testing'!$K$4:$K$47,"Blocked") -> 0 | H40: =COUNTIF('Regression Testing'!$K$4:$K$47,"Not Applicable") -> 0
A41: 19. End-to-End Scenarios | B41: 5 | C41: =COUNTA('End-to-End Scenarios'!$K$4:$K$80) -> 77 | D41: =COUNTIF('End-to-End Scenarios'!$K$4:$K$80,"Not Run")+COUNTBLANK('End-to-End Scenarios'!$K$4:$K$80) -> 77 | E41: =COUNTIF('End-to-End Scenarios'!$K$4:$K$80,"Pass") -> 0 | F41: =COUNTIF('End-to-End Scenarios'!$K$4:$K$80,"Fail") -> 0 | G41: =COUNTIF('End-to-End Scenarios'!$K$4:$K$80,"Blocked") -> 0 | H41: =COUNTIF('End-to-End Scenarios'!$K$4:$K$80,"Not Applicable") -> 0
A42: 20. Admin Customer Preview | B42: 24 | C42: =COUNTA('Admin Customer Preview'!$K$4:$K$162) -> 159 | D42: =COUNTIF('Admin Customer Preview'!$K$4:$K$162,"Not Run")+COUNTBLANK('Admin Customer Preview'!$K$4:$K$162) -> 159 | E42: =COUNTIF('Admin Customer Preview'!$K$4:$K$162,"Pass") -> 0 | F42: =COUNTIF('Admin Customer Preview'!$K$4:$K$162,"Fail") -> 0 | G42: =COUNTIF('Admin Customer Preview'!$K$4:$K$162,"Blocked") -> 0 | H42: =COUNTIF('Admin Customer Preview'!$K$4:$K$162,"Not Applicable") -> 0
A43: 21. Wizard Type Switching | B43: 11 | C43: =COUNTA('Wizard Type Switching'!$K$4:$K$97) -> 94 | D43: =COUNTIF('Wizard Type Switching'!$K$4:$K$97,"Not Run")+COUNTBLANK('Wizard Type Switching'!$K$4:$K$97) -> 94 | E43: =COUNTIF('Wizard Type Switching'!$K$4:$K$97,"Pass") -> 0 | F43: =COUNTIF('Wizard Type Switching'!$K$4:$K$97,"Fail") -> 0 | G43: =COUNTIF('Wizard Type Switching'!$K$4:$K$97,"Blocked") -> 0 | H43: =COUNTIF('Wizard Type Switching'!$K$4:$K$97,"Not Applicable") -> 0
...

Sheet Test Data
A1: TEST DATA — Business & Trade Account Manual Testing
A2: *** ALL DATA ON THIS SHEET IS FICTITIOUS TEST DATA. It does not represent any real customer, company, VAT registration or bank detail. Use it only against a non-production test environment. ***
A3: Read this sheet before starting. The application collects a SINGLE "name" field, not separate first/last names, and a SINGLE free-text "billing address" field, not separate city/county/country/Eircode fields. The requested test data has been mapped onto the fields the application actually has. Rows shaded amber are places where the originally requested value would be REJECTED by the application and has been corrected.
A5: ENVIRONMENT UNDER TEST
A6: Field | B6: Value to enter | C6: Notes
A7: Storefront base URL | B7: http://127.0.0.1:8000 | C7: Laravel APP_URL from .env. Confirm with the dev team before starting; substitute your own environment URL throughout the pack.
A8: Registration page | B8: {storefront}/register | C8: Multi-step wizard. Steps are driven by a ?step= query parameter: type, details, verify, security, done.
A9: Customer dashboard | B9: {storefront}/user/dashboard | C9: Shows the account headline and trade status.
A10: Customer profile | B10: {storefront}/user/profile | C10: Edit name, phone, company details and PO preference.
A11: Customer orders | B11: {storefront}/user/orders | C11: Order history; carries the Invoice action.
A12: Checkout | B12: {storefront}/checkout | C12: Signed-in checkout.
A13: Guest checkout | B13: {storefront}/guest-checkout | C13: Guest flow (no account).
A14: Admin panel base URL | B14: http://127.0.0.1:3001/admin/ | C14: Nuxt admin panel. In this project the admin dev server runs on port 3001 under the /admin/ path. Confirm before starting.
A15: Admin — trade queue | B15: {admin}/trade-applications | C15: Review queue: approve / reject / suspend trade applications.
A16: Admin — customers | B16: {admin}/registered-users | C16: Customer list; open a customer to see account type, status and business profile.
A17: Admin — quantity bands | B17: {admin}/business-products | C17: Where business/trade quantity band prices are created and edited.
... A19: Email capture | B19: Mailtrap / MailHog / real inbox | C19: Confirm with the dev team how outbound mail is captured in this environment BEFORE running the notification tests. If mail is discarded, mark those cases Blocked, not Failed.
A21: BUSINESS CUSTOMER — primary test account (TD-BUS-01)
A22: Field | B22: Value to enter | C22: Notes
A23: Account type | B23: Business | C23: Chosen on step 1 (type) of the registration wizard.
A24: Name | B24: Daniel Murphy | C24: The application has ONE name field. "Daniel" and "Murphy" are entered together here.
A25: Email | B25: business.test01@example.com | C25: Must be unique among VERIFIED accounts.
A26: Phone | B26: +353871234567 | C26: Must be unique among VERIFIED accounts. Used for the emailed/texted verification code.
A27: Password | B27: Business@2026Test! | C27: Meets the rule: at least 10 characters, one capital, one digit.
A28: Confirm password | B28: Business@2026Test! | C28: Must match exactly.
A29: Company name | B29: Murphy IT Solutions Ltd | C29: Required for Business accounts.
A30: Sector | B30: Professional services / office | C30: REQUIRED dropdown. Valid options only: Professional services / office | School or college | Medical or dental practice | Hospitality or retail | Construction or trades | Charity or community group | Other.
A31: VAT number | B31: IE1234567A | C31: Optional for Business. Format check only — 6-18 letters/digits with at least 2 digits. Must be unique across verified accounts.
A32: Company registration no. | B32: 123456 | C32: DIGITS ONLY, 4-12 digits. The originally requested "IE123456" WILL BE REJECTED with "A company registration number is digits only."
A33: Billing address | B33: 25 Main Street, Dublin, Dublin, D02 X285, Ireland | C33: ONE free-text field. There are no separate City / County / Country / Eircode inputs, so the whole address is typed into this box.
... A36: Terms | B36: Ticked | C36: Required. Unticked gives "Tick the box to continue."
A38: TRADE CUSTOMER — primary test account (TD-TRD-01)
A39: Field | B39: Value to enter | C39: Notes
A40: Account type | B40: Trade | C40: Chosen on step 1 (type) of the registration wizard.
A41: Name | B41: James O'Brien | C41: Single name field. The apostrophe is deliberate — it doubles as an input-hygiene check.
A42: Email | B42: trade.test01@example.com | C42: Must be unique among verified accounts.
A43: Phone | B43: +353861234567 | C43: Must be unique among verified accounts.
A44: Password | B44: Trade@2026Test! | C44: At least 10 characters, one capital, one digit.
A45: Company name | B45: O'Brien Electrical Services Ltd | C45: Required for Trade accounts.
A46: Trade | B46: Field engineer / sole trader | C46: REQUIRED dropdown. "Electrical Contractor" is NOT an option. Valid options only: Computer / laptop repair shop | Phone and tablet repair | IT reseller or MSP | Games console repair | Electronics or appliance repair | Field engineer / sole trader | Other.
...

Sheet Business Registration
A1: Business Registration
A2: Registration is a multi-step wizard at {storefront}/register: Type > Details > Verify > Security > Done. The application collects ONE name field and ONE free-text billing address. A Business account opens ACTIVE and gets band pricing immediately once the email is confirmed - it does not wait for staff verification.
A3: Test Case ID | B3: Module | C3: Test Scenario | D3: Priority | E3: Preconditions | F3: Test Data | G3: Step No. | H3: Action / Steps | I3: Expected Result | J3: Actual Result | K3: Status | L3: Severity | M3: Bug ID | N3: Tester Comments
A4: BRG-001 | B4: Business Registration | C4: Open the registration page and confirm the account-type step | D4: High | E4: No user signed in. Browser cache cleared. | F4: URL: {storefront}/register | G4: 1 | H4: Open a browser and go to {storefront}/register. | I4: The registration page loads with no PHP error, no blank screen and no console error. The first step is the account-type chooser. | K4: Not Run
A5: BRG-001 | B5: Business Registration | C5: Open the registration page and confirm the account-type step | D5: High | G5: 2 | H5: Look at the step indicator at the top of the form. | I5: Four steps are shown in order: Type, Details, Verify, Security. "Type" is the current step. | K5: Not Run
A6: BRG-001 | B6: Business Registration | C6: Open the registration page and confirm the account-type step | D6: High | G6: 3 | H6: Read the account type options offered. | I6: Exactly three choices are offered: Personal, Business and Trade. Record the wording of each. | K6: Not Run
A7: BRG-001 | B7: Business Registration | C7: Open the registration page and confirm the account-type step | D7: High | G7: 4 | H7: Check the browser address bar. | I7: The URL is {storefront}/register. The wizard tracks its position with a ?step= query parameter as you move forward. | K7: Not Run
A8: BRG-002 | B8: Business Registration | C8: Select Business and confirm the Business detail fields appear | D8: Critical | E8: BRG-001 done. | F8: Account type: Business | G8: 1 | H8: Select the Business account option and continue to the Details step. | I8: The form advances to Details. The URL gains ?step=details. The heading and intro text describe a business account. | K8: Not Run
A9: BRG-002 | B9: Business Registration | C9: Select Business and confirm the Business detail fields appear | D9: Critical | G9: 2 | H9: List every field shown on the Details step. | I9: The form shows: Name, Email, Phone, Password (and confirm), Company name, Sector (dropdown), VAT number, Company registration number, Billing address, "requires PO number" checkbox, "credit account application" checkbox, marketing preference checkboxes and a Terms checkbox. | K9: Not Run
A10: BRG-002 | B10: Business Registration | C10: Select Business and confirm the Business detail fields appear | D10: Critical | G10: 3 | H10: Open the Sector dropdown and read the options. | I10: Exactly seven options: Professional services / office | School or college | Medical or dental practice | Hospitality or retail | Construction or trades | Charity or community group | Other. | K10: Not Run
A11: BRG-002 | B11: Business Registration | C11: Select Business and confirm the Business detail fields appear | D11: Critical | G11: 4 | H11: Confirm there is NO separate first name and last name field. | I11: Correct - there is ONE Name field. Separate first/last name fields are Not Available / Not Implemented. Mark this step Not Applicable if you were expecting two fields; it is not a defect. | K11: Not Run
A12: BRG-002 | B12: Business Registration | C12: Select Business and confirm the Business detail fields appear | D12: Critical | G12: 5 | H12: Confirm there is NO separate City, County, Country or Eircode field. | I12: Correct - there is ONE free-text Billing address field. Structured address fields are Not Available / Not Implemented. | K12: Not Run
A13: BRG-002 | B13: Business Registration | C13: Select Business and confirm the Business detail fields appear | D13: Critical | G13: 6 | H13: Confirm there is NO "years in business" field. | I13: Correct - Not Available / Not Implemented for all account types. | K13: Not Run
A14: BRG-003 | B14: Business Registration | C14: Complete a valid Business registration end to end | D14: Critical | E14: BRG-002 done. The email address and phone number are not already on a verified account. | F14: Name: Daniel Murphy | Email: business.test01@example.com | Phone: +353871234567 | Password: Business@2026Test! | Company: Murphy IT Solutions Ltd | Sector: Professional services / office | VAT: IE1234567A | Company reg no: 123456 | Billing address: 25 Main Street, Dublin, Dublin, D02 X285, Ireland | Requires PO: ticked | Credit application: ticked | G14: 1 | H14: Enter Name: Daniel Murphy | I14: The field accepts the value with no error. | K14: Not Run
A15: BRG-003 | B15: Business Registration | C15: Complete a valid Business registration end to end | D15: Critical | G15: 2 | H15: Enter Email: business.test01@example.com | I15: Accepted, no inline error. | K15: Not Run
A16: BRG-003 | B16: Business Registration | C16: Complete a valid Business registration end to end | D16: Critical | G16: 3 | H16: Enter Phone: +353871234567 | I16: Accepted. If the form shows a country/format hint, the number is recognised as valid. | K16: Not Run
A17: BRG-003 | B17: Business Registration | C17: Complete a valid Business registration end to end | D17: Critical | G17: 4 | H17: Enter Password: Business@2026Test! and repeat it in the confirm field. | I17: Both accepted and they match. Any strength indicator shows the rule is met (10+ characters, a capital and a digit). | K17: Not Run
A18: BRG-003 | B18: Business Registration | C18: Complete a valid Business registration end to end | D18: Critical | G18: 5 | H18: Enter Company name: Murphy IT Solutions Ltd | I18: Accepted. | K18: Not Run
A19: BRG-003 | B19: Business Registration | C19: Complete a valid Business registration end to end | D19: Critical | G19: 6 | H19: Choose Sector: Professional services / office | I19: Accepted. | K19: Not Run
A20: BRG-003 | B20: Business Registration | C20: Complete a valid Business registration end to end | D20: Critical | G20: 7 | H20: Enter VAT number: IE1234567A | I20: Accepted. VAT is OPTIONAL for a Business account. | K20: Not Run
A21: BRG-003 | B21: Business Registration | C21: Complete a valid Business registration end to end | D21: Critical | G21: 8 | H21: Enter Company registration number: 123456 | I21: Accepted. NOTE: this field is digits only - entering "IE123456" would be rejected. | K21: Not Run
A22: BRG-003 | B22: Business Registration | C22: Complete a valid Business registration end to end | D22: Critical | G22: 9 | H22: Enter Billing address: 25 Main Street, Dublin, Dublin, D02 X285, Ireland | I22: Accepted as a single free-text value. | K22: Not Run
A23: BRG-003 | B23: Business Registration | C23: Complete a valid Business registration end to end | D23: Critical | G23: 10 | H23: Tick "requires PO number" and "credit account application". | I23: Both tick. These are preferences - the credit tick records interest only and does not grant a credit account. | K23: Not Run
A24: BRG-003 | B24: Business Registration | C24: Complete a valid Business registration end to end | D24: Critical | G24: 11 | H24: Tick the Terms checkbox and submit the Details step. | I24: The form submits with no validation error and moves to the Verify step (?step=verify). | K24: Not Run
A25: BRG-003 | B25: Business Registration | C25: Complete a valid Business registration end to end | D25: Critical | G25: 12 | H25: Read the Verify step. | I25: It asks for a verification code and states where the code was sent. Retrieve the code from the configured mail capture tool. | K25: Not Run
A26: BRG-003 | B26: Business Registration | C26: Complete a valid Business registration end to end | D26: Critical | G26: 13 | H26: Enter the correct verification code and continue. | I26: The code is accepted and the wizard advances to the Security step (two-factor setup). | K26: Not Run
... A28: BRG-003 | B28: Business Registration | C28: Complete a valid Business registration end to end | D28: Critical | G28: 15 | H28: Read the confirmation on the Done step. | I28: It confirms the account is created. Record the exact wording in Actual Result. | K28: Not Run
A29: BRG-004 | B29: Business Registration | C29: Verify the Business account was created with the right state | D29: Critical | E29: BRG-003 completed successfully. | F29: Email: business.test01@example.com | G29: 1 | H29: Sign in to the storefront as business.test01@example.com. | I29: Sign-in succeeds and the customer dashboard loads. | K29: Not Run
A30: BRG-004 | B30: Business Registration | C30: Verify the Business account was created with the right state | D30: Critical | G30: 2 | H30: Open {storefront}/user/dashboard and read the account section. | I30: The account is shown as a Business account and as active. A one-line headline describes the account state. | K30: Not Run
A31: BRG-004 | B31: Business Registration | C31: Verify the Business account was created with the right state | D31: Critical | G31: 3 | H31: Confirm the dashboard does NOT show a trade application or a pending trade status. | I31: Correct - trade status belongs to Trade accounts only. A Business account has no trade application. | K31: Not Run
A32: BRG-004 | B32: Business Registration | C32: Verify the Business account was created with the right state | D32: Critical | G32: 4 | H32: In the admin panel open {admin}/registered-users and find business.test01@example.com. | I32: The customer is listed with account type Business. | K32: Not Run
A33: BRG-004 | B33: Business Registration | C33: Verify the Business account was created with the right state | D33: Critical | G33: 5 | H33: Open that customer record in admin. | I33: Account type = business; account status = active; verification status = pending (company details not yet checked by staff); trade status = empty/none. | K33: Not Run
A34: BRG-004 | B34: Business Registration | C34: Verify the Business account was created with the right state | D34: Critical | G34: 6 | H34: Confirm the business pricing entitlement on the admin record. | I34: The record shows the account IS entitled to business pricing. A Business account qualifies at signup - it does NOT have to wait for staff verification. Verification status and pricing entitlement are two separate facts. | K34: Not Run
A35: BRG-005 | B35: Business Registration | C35: Verify every value entered at registration was stored | D35: High | E35: BRG-004 done. | F35: All values from BRG-003. | G35: 1 | H35: In admin, open the customer record for business.test01@example.com and find the business profile section. | I35: A business profile exists for this customer. | K35: Not Run
A36: BRG-005 | B36: Business Registration | C36: Verify every value entered at registration was stored | D36: High | G36: 2 | H36: Compare Company name against what you typed. | I36: Shows exactly: Murphy IT Solutions Ltd | K36: Not Run
A37: BRG-005 | B37: Business Registration | C37: Verify every value entered at registration was stored | D37: High | G37: 3 | H37: Compare VAT number. | I37: Shows exactly: IE1234567A | K37: Not Run
A38: BRG-005 | B38: Business Registration | C38: Verify every value entered at registration was stored | D38: High | G38: 4 | H38: Compare Company registration number. | I38: Shows exactly: 123456 | K38: Not Run
A39: BRG-005 | B39: Business Registration | C39: Verify every value entered at registration was stored | D39: High | G39: 5 | H39: Compare Billing address. | I39: Shows the full address string exactly as typed, including the Eircode text. | K39: Not Run
A40: BRG-005 | B40: Business Registration | C40: Verify every value entered at registration was stored | D40: High | G40: 6 | H40: Compare Sector. | I40: Shows: Professional services / office | K40: Not Run
A41: BRG-005 | B41: Business Registration | C41: Verify every value entered at registration was stored | D41: High | G41: 7 | H41: Compare the PO requirement flag. | I41: Shows that this account requires a PO number. | K41: Not Run
...

Sheet Business Profile
A1: Business Profile
A2: The customer profile at {storefront}/user/profile. Name, phone and marketing preferences are the customer's own; company details are editable here too. Account TYPE is not editable by the customer - and there is no workflow anywhere to change it.
A3: Test Case ID | B3: Module | C3: Test Scenario | D3: Priority | E3: Preconditions | F3: Test Data | G3: Step No. | H3: Action / Steps | I3: Expected Result | J3: Actual Result | K3: Status | L3: Severity | M3: Bug ID | N3: Tester Comments
A4: BPR-001 | B4: Business Profile | C4: Open the Business profile and verify the registration data is all there | D4: Critical | E4: Signed in as business.test01@example.com. | F4: All values from BRG-003. | G4: 1 | H4: Sign in as business.test01@example.com and open {storefront}/user/profile. | I4: The profile page loads with no error. | K4: Not Run
A5: BPR-001 | B5: Business Profile | C5: Open the Business profile and verify the registration data is all there | D5: Critical | G5: 2 | H5: Compare the Name shown against what was registered. | I5: Shows: Daniel Murphy | K5: Not Run
A6: BPR-001 | B6: Business Profile | C6: Open the Business profile and verify the registration data is all there | D6: Critical | G6: 3 | H6: Compare the Email shown. | I6: Shows: business.test01@example.com | K6: Not Run
A7: BPR-001 | B7: Business Profile | C7: Open the Business profile and verify the registration data is all there | D7: Critical | G7: 4 | H7: Compare the Phone shown. | I7: Shows: +353871234567 | K7: Not Run
A8: BPR-001 | B8: Business Profile | C8: Open the Business profile and verify the registration data is all there | D8: Critical | G8: 5 | H8: Compare the Company name shown. | I8: Shows: Murphy IT Solutions Ltd | K8: Not Run
A9: BPR-001 | B9: Business Profile | C9: Open the Business profile and verify the registration data is all there | D9: Critical | G9: 6 | H9: Compare the VAT number shown. | I9: Shows: IE1234567A | K9: Not Run
A10: BPR-001 | B10: Business Profile | C10: Open the Business profile and verify the registration data is all there | D10: Critical | G10: 7 | H10: Compare the Company registration number shown. | I10: Shows: 123456 | K10: Not Run
A11: BPR-001 | B11: Business Profile | C11: Open the Business profile and verify the registration data is all there | D11: Critical | G11: 8 | H11: Compare the Billing address shown. | I11: Shows the full address as registered. | K11: Not Run
A12: BPR-001 | B12: Business Profile | C12: Open the Business profile and verify the registration data is all there | D12: Critical | G12: 9 | H12: Compare the Sector shown. | I12: Shows: Professional services / office | K12: Not Run
A13: BPR-001 | B13: Business Profile | C13: Open the Business profile and verify the registration data is all there | D13: Critical | G13: 10 | H13: Compare the PO requirement setting. | I13: Shows that a PO number is required for this account (it was ticked at registration). | K13: Not Run
A14: BPR-001 | B14: Business Profile | C14: Open the Business profile and verify the registration data is all there | D14: Critical | G14: 11 | H14: Confirm nothing entered at registration is missing from this screen. | I14: Every value entered during registration is either shown or accounted for. List anything missing in Actual Result - a value collected at registration but never shown back is a defect. | K14: Not Run
A15: BPR-002 | B15: Business Profile | C15: Edit the name and confirm it persists | D15: High | E15: Signed in as business.test01@example.com. | F15: New name: Daniel J Murphy | G15: 1 | H15: Change the Name field to "Daniel J Murphy" and save. | I15: Saved with a success confirmation. | K15: Not Run
A16: BPR-002 | B16: Business Profile | C16: Edit the name and confirm it persists | D16: High | G16: 2 | H16: Refresh the page. | I16: The name still shows Daniel J Murphy. | K16: Not Run
A17: BPR-002 | B17: Business Profile | C17: Edit the name and confirm it persists | D17: High | G17: 3 | H17: Sign out and sign back in, then reopen the profile. | I17: The name is still Daniel J Murphy. | K17: Not Run
A18: BPR-002 | B18: Business Profile | C18: Edit the name and confirm it persists | D18: High | G18: 4 | H18: Check the same customer in the admin panel. | I18: Admin shows the updated name. | K18: Not Run
A19: BPR-002 | B19: Business Profile | C19: Edit the name and confirm it persists | D19: High | G19: 5 | H19: Confirm the marketing preferences and company details were NOT wiped by saving the name alone. | I19: Company name, VAT number, billing address and the preference checkboxes are all unchanged. Saving one field must not blank the others. | K19: Not Run
A20: BPR-003 | B20: Business Profile | C20: Edit the phone number and confirm it is treated as unproved | D20: High | E20: Signed in as business.test01@example.com. | F20: New phone: +353871234571 | G20: 1 | H20: Change the Phone to +353871234571 and save. | I20: Saved. | K20: Not Run
A21: BPR-003 | B21: Business Profile | C21: Edit the phone number and confirm it is treated as unproved | D21: High | G21: 2 | H21: Refresh and confirm the new number is shown. | I21: Shows +353871234571. | K21: Not Run
A22: BPR-003 | B22: Business Profile | C22: Edit the phone number and confirm it is treated as unproved | D22: High | G22: 3 | H22: Check whether the account still claims the phone number is verified. | I22: The new number is NOT treated as verified - changing the number clears any previous phone verification. A number that has never been texted must not be shown as proved. | K22: Not Run
A23: BPR-003 | B23: Business Profile | C23: Edit the phone number and confirm it is treated as unproved | D23: High | G23: 4 | H23: If two-factor by SMS was enabled, check what happened to it. | I23: Record the behaviour. The second factor must not silently point at an unproved number. | K23: Not Run
A24: BPR-003 | B24: Business Profile | C24: Edit the phone number and confirm it is treated as unproved | D24: High | G24: 5 | H24: Change the phone back to +353871234567. | I24: Saved, and again treated as unverified until proved. | K24: Not Run
A25: BPR-004 | B25: Business Profile | C25: Edit the billing address and company details | D25: High | E25: Signed in as business.test01@example.com. | F25: New address: 26 Main Street, Dublin, Dublin, D02 X286, Ireland | New company: Murphy IT Solutions Limited | G25: 1 | H25: Change the Billing address to "26 Main Street, Dublin, Dublin, D02 X286, Ireland" and save. | I25: Saved with a confirmation. | K25: Not Run
A26: BPR-004 | B26: Business Profile | C26: Edit the billing address and company details | D26: High | G26: 2 | H26: Refresh, then sign out and back in. | I26: The new address persists. | K26: Not Run
A27: BPR-004 | B27: Business Profile | C27: Edit the billing address and company details | D27: High | G27: 3 | H27: Change the Company name to "Murphy IT Solutions Limited" and save. | I27: Saved. | K27: Not Run
A28: BPR-004 | B28: Business Profile | C28: Edit the billing address and company details | D28: High | G28: 4 | H28: Confirm in the admin customer record. | I28: Admin shows the updated company name and address. | K28: Not Run
A29: BPR-004 | B29: Business Profile | C29: Edit the billing address and company details | D29: High | G29: 5 | H29: Clear the Billing address entirely and save. | I29: Record the behaviour. If the field is required here it should be refused with a clear message; if it is allowed to be emptied, note that a VAT invoice would then have no address. | K29: Not Run
A30: BPR-005 | B30: Business Profile | C30: Edit the VAT number from the profile | D30: High | E30: Signed in as business.test01@example.com. A second verified account exists holding VAT IE2222222C. | F30: Valid: IE1234567B | Invalid: n/a | Taken: IE2222222C | G30: 1 | H30: Change the VAT number to "n/a" and save. | I30: Refused with: "That does not look like a VAT number. Enter it as it appears on your VAT certificate." | K30: Not Run
A31: BPR-005 | B31: Business Profile | C31: Edit the VAT number from the profile | D31: High | G31: 2 | H31: Change the VAT number to IE2222222C, which belongs to another verified account, and save. | I31: REFUSED - another company's VAT number cannot be edited in from the profile. Record the exact message. | K31: Not Run
A32: BPR-005 | B32: Business Profile | C32: Edit the VAT number from the profile | D32: High | G32: 3 | H32: Change the VAT number to IE1234567B and save. | I32: Accepted and saved. | K32: Not Run
A33: BPR-005 | B33: Business Profile | C33: Edit the VAT number from the profile | D33: High | G33: 4 | H33: Refresh and confirm. | I33: Shows IE1234567B. | K33: Not Run
A34: BPR-005 | B34: Business Profile | C34: Edit the VAT number from the profile | D34: High | G34: 5 | H34: Set the VAT number back to IE1234567A for the rest of the pack. | I34: Saved. | K34: Not Run
A35: BPR-006 | B35: Business Profile | C35: Change the PO requirement and confirm it gates checkout | D35: Critical | E35: Signed in as business.test01@example.com. | F35: PO toggle on the profile; PO-2026-00125 at checkout. | G35: 1 | H35: On the profile, UNTICK "requires PO number" and save. | I35: Saved. | K35: Not Run
A36: BPR-006 | B36: Business Profile | C36: Change the PO requirement and confirm it gates checkout | D36: Critical | G36: 2 | H36: Add 'testing product' (product ID 99240288, slug testing-product, retail EUR 505.00 ex VAT) to the basket and go to checkout. Leave the PO field empty. | I36: Checkout is allowed to proceed without a PO number. | K36: Not Run
A37: BPR-006 | B37: Business Profile | C37: Change the PO requirement and confirm it gates checkout | D37: Critical | G37: 3 | H37: Return to the profile, TICK "requires PO number" and save. | I37: Saved. | K37: Not Run
A38: BPR-006 | B38: Business Profile | C38: Change the PO requirement and confirm it gates checkout | D38: Critical | G38: 4 | H38: Go to checkout again and leave the PO number empty, then try to place the order. | I38: REFUSED with: "Enter the purchase order number for this order." | K38: Not Run
A39: BPR-006 | B39: Business Profile | C39: Change the PO requirement and confirm it gates checkout | D39: Critical | G39: 5 | H39: Enter PO-2026-00125 and place the order. | I39: Accepted. The preference set on the profile is what gates checkout. | K39: Not Run
A40: BPR-007 | B40: Business Profile | C40: The account type cannot be changed by the customer | D40: Critical | E40: Signed in as business.test01@example.com. | F40: Attempt to set account_type to trade. | G40: 1 | H40: Look on the profile page for any control to change the account type from Business to Trade or Personal. | I40: There is NO such control. An account-type change workflow is Not Available / Not Implemented - a different type means a new registration. Mark Not Applicable, not Fail. | K40: Not Run
...

Sheet Trade Registration
A1: Trade Registration
A2: A Trade account opens ACTIVE but with trade status PENDING, and buys at RETAIL until staff approve it. VAT number, trade type, expected spend and the resale confirmation are all REQUIRED for Trade - unlike Business, where VAT is optional.
A3: Test Case ID | B3: Module | C3: Test Scenario | D3: Priority | E3: Preconditions | F3: Test Data | G3: Step No. | H3: Action / Steps | I3: Expected Result | J3: Actual Result | K3: Status | L3: Severity | M3: Bug ID | N3: Tester Comments
A4: TRG-001 | B4: Trade Registration | C4: Select Trade and confirm the Trade detail fields | D4: Critical | E4: No user signed in. | F4: URL: {storefront}/register | G4: 1 | H4: Open {storefront}/register and choose the Trade account type, then continue. | I4: The Details step opens with Trade-specific text explaining that the account works at retail prices immediately and trade pricing switches on after approval. | K4: Not Run
A5: TRG-001 | B5: Trade Registration | C5: Select Trade and confirm the Trade detail fields | D5: Critical | G5: 2 | H5: List every field on the Trade Details step. | I5: Name, Email, Phone, Password + confirm, Company name, Trade (dropdown), VAT number, Company registration number, Billing address, Expected monthly spend (dropdown), Website, resale confirmation checkbox, marketing preferences, Terms. | K5: Not Run
A6: TRG-001 | B6: Trade Registration | C6: Select Trade and confirm the Trade detail fields | D6: Critical | G6: 3 | H6: Open the Trade dropdown and read the options. | I6: Exactly seven: Computer / laptop repair shop | Phone and tablet repair | IT reseller or MSP | Games console repair | Electronics or appliance repair | Field engineer / sole trader | Other. NOTE "Electrical Contractor" is NOT an option - use "Field engineer / sole trader" or "Other". | K6: Not Run
A7: TRG-001 | B7: Trade Registration | C7: Select Trade and confirm the Trade detail fields | D7: Critical | G7: 4 | H7: Open the Expected monthly spend dropdown. | I7: Exactly four: Under EUR 500 | EUR 500 - 2,000 | EUR 2,000 - 5,000 | Over EUR 5,000. | K7: Not Run
A8: TRG-001 | B8: Trade Registration | C8: Select Trade and confirm the Trade detail fields | D8: Critical | G8: 5 | H8: Confirm there is NO "sector" field on the Trade form. | I8: Correct - sector belongs to Business; trade type is the Trade equivalent. | K8: Not Run
A9: TRG-001 | B9: Trade Registration | C9: Select Trade and confirm the Trade detail fields | D9: Critical | G9: 6 | H9: Confirm there is NO "requires PO" or "credit application" checkbox on the Trade form. | I9: Correct - those are collected for Business accounts at registration. Record whether the PO preference can be set later from the Trade profile. | K9: Not Run
