Workbook

Sheet Cover
B2: FixMyPC - Master Test Case Suite
B4: Laravel 8 API + Nuxt admin panel and storefront - multi-vendor e-commerce platform
B6: Document | C6: Master Test Case Suite
B7: Version | C7: 1
B8: Prepared | C8: 09 Sep 2026
B9: Total test cases | C9: 642
B10: Application under test | C10: FixMyPC (Laravel 8 REST API, Nuxt admin-panel, Nuxt frontend-panel)
B11: Scope | C11: Authentication, RBAC, catalogue, inventory, pricing and promotions, vouchers, cart, checkout, payments, orders, wallet and loyalty, storefront, search, reviews, vendor and procurement, POS, CMS, settings, customer account, security, API, performance, responsive, accessibility, compatibility, localisation, database, error handling, installation and end-to-end journeys.
B12: Out of scope | C12: Third-party gateway internals, ISP and DNS infrastructure, and any module explicitly deferred by the release plan.
B14: HOW TO USE THIS WORKBOOK
B15: Test Cases | C15: The master sheet. One row per test case. Filters are on and the header row is frozen. Fill in Actual Result and Status as you execute; everything else is pre-written.
B16: Status values | C16: Not Executed / Pass / Fail / Blocked / Deferred / N-A. Pick from the dropdown - the Dashboard counts depend on these exact values.
B17: Priority | C17: High / Medium / Low - execution order. Run every High case before any Medium.
B18: Severity | C18: Blocker / Critical / Major / Minor - the business impact if the case fails. Any Blocker failure stops the release.
B19: Dashboard | C19: Live counts by status, priority, severity and module. It reads the Test Cases sheet directly, so it updates as you fill Status in.
B20: Defect Log | C20: Raise one row per failure. Reference the Test Case ID so a defect always traces back to a case.
B21: Test Data | C21: Shared accounts, cards, and reference values used across the suite. Set these up before the first cycle.
B22: Environments | C22: The browser, device and environment matrix the Environment column refers to.
B23: Traceability | C23: Module-level coverage summary - which areas are covered, by how many cases, and at what risk weighting.
B25: NOTE ON RISK-WEIGHTED CASES
B26: Cases whose Remarks cite a QA audit reference (for example ORD-01, PRC-03, PAY-01, SEC-03, STK-02) are regression checks against findings recorded in reference/qa/qa-audit-2026-09-09.html. They target known weak points in pricing reconciliation, payment verification, stock handling, order lifecycle and access control, and should be executed first in every cycle regardless of module order.

Sheet Test Cases
A1: Test Case ID | B1: Module | C1: Feature / Functionality | D1: Test Scenario | E1: Preconditions | F1: Test Steps | G1: Test Data | H1: Expected Result | I1: Actual Result | J1: Priority | K1: Severity | L1: Test Type | M1: Environment | N1: Status | O1: Remarks
A2: AUTH-001 | B2: Authentication | C2: Personal account registration | D2: Register a new Personal account with all valid details | E2: Storefront reachable; email not already in the users table | F2: 1. Open /register 2. Choose account type "Personal" 3. Enter name, email, phone and password 4. Tick the terms checkbox 5. Click Register | G2: name=John Tester; email=qa.personal01@example.com; phone=+447700900001; password=Passw0rdTest1 | H2: HTTP 200; account created; verification code emailed; user advanced to the verify step; users row stores a bcrypt hash, never plain text | J2: High | K2: Critical | L2: Functional / Positive | M2: Staging - Chrome 126 (Win 11) | N2: Not Executed
A3: AUTH-002 | B3: Authentication | C3: Business account registration | D3: Register a Business account supplying the company block | E3: Email not registered | F3: 1. Open /register 2. Choose "Business" 3. Fill the base fields 4. Fill company_name, sector, billing_address 5. Submit | G3: company_name=Acme Ltd; sector=Retail; billing_address=1 High St, London, E1 6AN | H3: Account created with account_type=business and the user_business_profiles row persisted | J3: High | K3: Major | L3: Functional / Positive | M3: Staging - Chrome 126 (Win 11) | N3: Not Executed
A4: AUTH-003 | B4: Authentication | C4: Trade account registration | D4: Register a Trade account supplying the full trade block | E4: Email not registered | F4: 1. Open /register 2. Choose "Trade" 3. Fill base plus company_name, trade, vat_number, billing_address, expected_spend 4. Tick the resale confirmation 5. Submit | G4: vat_number=GB123456789; trade=IT Services; expected_spend=25000 | H4: Trade application created in pending state; account_type=trade; the record appears under Admin > Trade Applications | J4: High | K4: Major | L4: Functional / Positive | M4: Staging - Chrome 126 (Win 11) | N4: Not Executed
A5: AUTH-004 | B5: Authentication | C5: Registration - required fields | D5: Submit the registration form completely blank | E5: On /register | F5: 1. Open /register 2. Click Register without entering anything | G5: all fields empty | H5: Inline errors on name, email, phone, account_type, password and terms; no user row is created | J5: High | K5: Major | L5: Validation / Negative | M5: Staging - Chrome 126 (Win 11) | N5: Not Executed
A6: AUTH-005 | B6: Authentication | C6: Registration - email format | D6: Reject malformed email addresses | E6: On /register | F6: 1. Enter each malformed value in the email field 2. Submit | G6: plainaddress | qa@ | @example.com | qa@@example.com | qa me@example.com | qa@example | H6: "Enter a valid email" is shown for every value; no account is created | J6: High | K6: Major | L6: Validation / Negative | M6: Staging - Chrome 126 (Win 11) | N6: Not Executed
A7: AUTH-006 | B7: Authentication | C7: Registration - password strength | D7: Password must be at least 10 chars with a capital and a digit | E7: On /register | F7: 1. Try each password value in turn 2. Submit | G7: Short1 | alllowercase1 | ALLUPPERCASE1 | NoDigitsHere | Passw0rdTest1 | H7: The first four are rejected with "Use at least 10 characters, with a capital letter and a number."; the last is accepted | J7: High | K7: Major | L7: Validation / Negative | M7: Staging - Chrome 126 (Win 11) | N7: Not Executed
A8: AUTH-007 | B8: Authentication | C8: Registration - password boundary | D8: Exactly 9 / 10 / 11 characters with capital plus digit | E8: On /register | F8: 1. Submit each password value in turn | G8: Passwor1A (9) | Password1A (10) | Password12A (11) | H8: 9 chars rejected; 10 and 11 accepted - confirms min:10 is inclusive | J8: Medium | K8: Minor | L8: Boundary | M8: Staging - Chrome 126 (Win 11) | N8: Not Executed
A9: AUTH-008 | B9: Authentication | C9: Registration - duplicate email | D9: Register twice with the same email address | E9: qa.personal01@example.com already registered | F9: 1. Register again using the same email | G9: email=qa.personal01@example.com | H9: Rejected with a duplicate-email message; exactly one users row exists | J9: High | K9: Major | L9: Negative | M9: Staging - Chrome 126 (Win 11) | N9: Not Executed
A10: AUTH-009 | B10: Authentication | C10: Registration - duplicate email casing | D10: Same address supplied in a different letter case | E10: qa.personal01@example.com exists | F10: 1. Register with QA.Personal01@Example.com | G10: QA.Personal01@Example.com | H10: Treated as the same account and rejected - email matching must be case-insensitive | J10: Medium | K10: Major | L10: Negative / Edge | M10: Staging - Chrome 126 (Win 11) | N10: Not Executed
A11: AUTH-010 | B11: Authentication | C11: Registration - terms checkbox | D11: Submit without accepting the terms | E11: All other fields valid | F11: 1. Fill the form 2. Leave the terms box unticked 3. Submit | G11: terms=unchecked | H11: "Tick the box to continue." is shown and registration is blocked | J11: Medium | K11: Minor | L11: Validation / Negative | M11: Staging - Chrome 126 (Win 11) | N11: Not Executed
A12: AUTH-011 | B12: Authentication | C12: Trade - resale confirmation | D12: Trade signup without resale_confirmed | E12: Account type set to Trade | F12: 1. Fill the trade fields 2. Leave the resale confirmation unticked 3. Submit | G12: resale_confirmed=false | H12: "Trade accounts need this confirmation." is shown; signup blocked | J12: Medium | K12: Minor | L12: Validation / Negative | M12: Staging - Chrome 126 (Win 11) | N12: Not Executed
A13: AUTH-012 | B13: Authentication | C13: Registration - account_type whitelist | D13: Post an account_type outside the allowed set | E13: API client with an otherwise valid payload | F13: 1. POST /api/user/signup with account_type=superadmin | G13: account_type=superadmin | H13: Validation error - only personal, business and trade are accepted; no privileged account is created | J13: High | K13: Critical | L13: Security / Negative | M13: Staging - Postman / REST client | N13: Not Executed | O13: Mass-assignment probe
A14: AUTH-013 | B14: Authentication | C14: Registration - field length limits | D14: Very long values in name and email | E14: On /register | F14: 1. Paste a 300-character name and a 250-character local part 2. Submit | G14: name = A x300; email = <250 chars>@example.com | H14: Values are rejected or safely truncated to the column width; no HTTP 500 and no SQL truncation warning | J14: Medium | K14: Minor | L14: Boundary / Negative | M14: Staging - Chrome 126 (Win 11) | N14: Not Executed
A15: AUTH-014 | B15: Authentication | C15: Registration - script injection | D15: HTML/JS payload in the name field | E15: On /register | F15: 1. Enter the payload as the name 2. Register 3. View the name in the profile and in the admin user list | G15: name=<script>alert(1)</script> | H15: The value is stored escaped and rendered as literal text in both storefront and admin; no alert fires | J15: High | K15: Critical | L15: Security / XSS | M15: Staging - Chrome 126 (Win 11) | N15: Not Executed
A16: AUTH-015 | B16: Authentication | C16: Email verification code | D16: Verify a new account with the emailed code | E16: Account registered and code sent | F16: 1. Read the code from the inbox 2. Enter it on the verify screen 3. Submit | G16: code = value from email | H16: Account is marked verified and the user is signed in or sent to login | J16: High | K16: Critical | L16: Functional / Positive | M16: Staging - Chrome 126 (Win 11) | N16: Not Executed
A17: AUTH-016 | B17: Authentication | C17: Email verification - wrong code | D17: Enter an incorrect verification code | E17: Account awaiting verification | F17: 1. Enter a wrong 4-6 digit code 2. Submit | G17: code=0000 | H17: Rejected with a generic error; the account stays unverified | J17: High | K17: Major | L17: Negative | M17: Staging - Chrome 126 (Win 11) | N17: Not Executed
A18: AUTH-017 | B18: Authentication | C18: Verification code brute force | D18: Repeatedly guess the verification code | E18: Account awaiting verification | F18: 1. POST /api/user/verify 25 times with different codes within one minute | G18: codes 0000 to 0024 | H18: Attempts are throttled or locked after a small number of failures and the code is invalidated - guessing must not be unlimited | J18: High | K18: Critical | L18: Security / Negative | M18: Staging - Postman / REST client | N18: Not Executed | O18: QA audit flagged codes as brute-forceable; regression check
A19: AUTH-018 | B19: Authentication | C19: Verification code expiry | D19: Use a code after its validity window | E19: Code issued longer ago than the configured TTL | F19: 1. Wait past the TTL 2. Submit the old code | G19: stale code | H19: Rejected as expired; a fresh code can be requested | J19: Medium | K19: Major | L19: Negative / Boundary | M19: Staging - Chrome 126 (Win 11) | N19: Not Executed
A20: AUTH-019 | B20: Authentication | C20: Login with valid credentials | D20: Sign in as a verified customer | E20: Verified account exists | F20: 1. Open /login 2. Enter email and password 3. Submit | G20: qa.personal01@example.com / Passw0rdTest1 | H20: HTTP 200; a Passport token carrying the user scope is returned; the user lands on the dashboard and the header shows the account menu | J20: High | K20: Critical | L20: Functional / Positive | M20: Staging - Chrome 126 (Win 11) | N20: Not Executed
A21: AUTH-020 | B21: Authentication | C21: Login with wrong password | D21: Sign in with a bad password | E21: Account exists | F21: 1. Enter a valid email with the wrong password 2. Submit | G21: qa.personal01@example.com / WrongPass99 | H21: Generic invalid-credentials error; no token issued; the message does not reveal whether the email exists | J21: High | K21: Critical | L21: Negative / Security | M21: Staging - Chrome 126 (Win 11) | N21: Not Executed
A22: AUTH-021 | B22: Authentication | C22: Login - unknown email | D22: Sign in with an email that is not registered | E22: No matching account | F22: 1. Enter an unregistered email with any password 2. Submit | G22: nobody@example.com / Passw0rdTest1 | H22: The same generic error and a comparable response time as AUTH-020 - no account enumeration | J22: High | K22: Major | L22: Security / Negative | M22: Staging - Chrome 126 (Win 11) | N22: Not Executed
A23: AUTH-022 | B23: Authentication | C23: Login - unverified account | D23: Sign in before verifying the email | E23: Account registered but not verified | F23: 1. Attempt to log in | G23: unverified account | H23: Blocked with a verify-your-email prompt and an option to resend the code | J23: Medium | K23: Major | L23: Negative | M23: Staging - Chrome 126 (Win 11) | N23: Not Executed
A24: AUTH-023 | B24: Authentication | C24: Login - deactivated account | D24: Sign in to a deactivated or blocked account | E24: Admin has deactivated the account | F24: 1. Attempt to log in | G24: deactivated account | H24: Login refused with an account-disabled message; no token issued | J24: High | K24: Major | L24: Negative | M24: Staging - Chrome 126 (Win 11) | N24: Not Executed
A25: AUTH-024 | B25: Authentication | C25: Login - password minimum length | D25: Password shorter than the 6-character API rule | E25: API client available | F25: 1. POST /api/user/signin with a 5-character password | G25: password=Abc12 | H25: Validation error returned before any credential check runs | J25: Low | K25: Minor | L25: Validation / Boundary | M25: Staging - Postman / REST client | N25: Not Executed
A26: AUTH-025 | B26: Authentication | C26: Login rate limiting | D26: Repeated failed logins from one client | E26: Account exists | F26: 1. Submit 20 wrong passwords for the same email within a minute | G26: 20 x WrongPass | H26: Throttling or lockout applies (HTTP 429 or a cooldown message); the correct password still works after the cooldown | J26: High | K26: Critical | L26: Security / Performance | M26: Staging - Postman / REST client | N26: Not Executed
A27: AUTH-026 | B27: Authentication | C27: Login - SQL injection | D27: SQL payloads in the login fields | E27: Login page open | F27: 1. Enter the payload as the email and then as the password 2. Submit | G27: OR 1=1 -- ; admin'-- | H27: Treated as literal text; login fails; no SQL error surfaces and no session is created | J27: High | K27: Critical | L27: Security / Negative | M27: Staging - Chrome 126 (Win 11) | N27: Not Executed
A28: AUTH-027 | B28: Authentication | C28: Passwordless login code - send | D28: Request a one-time login code by email | E28: Verified account exists | F28: 1. POST /api/user/login-code with the email | G28: email=qa.personal01@example.com | H28: A code is emailed; the response does not disclose whether the address exists | J28: Medium | K28: Major | L28: Functional / Positive | M28: Staging - Postman / REST client | N28: Not Executed
A29: AUTH-028 | B29: Authentication | C29: Passwordless login code - verify | D29: Sign in using a valid one-time code | E29: Code just requested | F29: 1. POST /api/user/login-code/verify with email plus code | G29: email plus valid code | H29: A token is issued and the code is consumed - replaying the same code fails | J29: High | K29: Critical | L29: Functional / Positive | M29: Staging - Postman / REST client | N29: Not Executed
A30: AUTH-029 | B30: Authentication | C30: Login code - reuse | D30: Reuse an already-consumed login code | E30: Code used once in AUTH-028 | F30: 1. POST the same code a second time | G30: used code | H30: Rejected - single use is enforced | J30: High | K30: Major | L30: Negative / Security | M30: Staging - Postman / REST client | N30: Not Executed
... A37: AUTH-036 | B37: Authentication | C37: Forgot password - existing email | D37: Request a password reset link | E37: Account exists | F37: 1. Open /forgot-password 2. Enter the email 3. Submit | G37: qa.personal01@example.com | H37: A neutral confirmation is shown and a reset email with a single-use token is delivered | J37: High | K37: Major | L37: Functional / Positive | M37: Staging - Chrome 126 (Win 11) | N37: Not Executed
A38: AUTH-037 | B38: Authentication | C38: Forgot password - unknown email | D38: Request a reset for an address that does not exist | E38: No matching account | F38: 1. Submit an unregistered email | G38: nobody@example.com | H38: Identical wording and comparable timing to AUTH-036 - the response must not enumerate accounts | J38: High | K38: Major | L38: Security / Negative | M38: Staging - Chrome 126 (Win 11) | N38: Not Executed | O38: QA audit flagged reset-flow enumeration
A39: AUTH-038 | B39: Authentication | C39: Reset password - valid token | D39: Set a new password from the emailed link | E39: Reset token issued | F39: 1. Open the emailed link 2. Enter a new password twice 3. Submit | G39: password=NewPassw0rd1 | H39: The password is updated, the token is consumed, the old password stops working, and existing sessions are invalidated | J39: High | K39: Critical | L39: Functional / Positive | M39: Staging - Chrome 126 (Win 11) | N39: Not Executed
A40: AUTH-039 | B40: Authentication | C40: Reset password - token reuse or tamper | D40: Reuse or alter the reset token | E40: Token already used in AUTH-038 | F40: 1. Reopen the same link 2. Then open the link with one character changed | G40: used token; tampered token | H40: Both are rejected with "This reset link is not valid." | J40: High | K40: Critical | L40: Security / Negative | M40: Staging - Chrome 126 (Win 11) | N40: Not Executed
A41: AUTH-040 | B41: Authentication | C41: Reset password - expired token | D41: Use a reset token after its lifetime | E41: Token older than the configured expiry | F41: 1. Open the stale link 2. Submit a new password | G41: expired token | H41: Rejected as expired, with a way to request a fresh link | J41: Medium | K41: Major | L41: Negative / Boundary | M41: Staging - Chrome 126 (Win 11) | N41: Not Executed
A42: AUTH-041 | B42: Authentication | C42: Reset password - strength rule | D42: The new password must meet the 10/capital/digit rule | E42: Valid reset token | F42: 1. Try weak values, then a compliant one | G42: abc | Password1 (9) | Password1A (10) | H42: The first two are rejected with the strength message; the 10-character value is accepted | J42: Medium | K42: Major | L42: Validation / Boundary | M42: Staging - Chrome 126 (Win 11) | N42: Not Executed
A43: AUTH-042 | B43: Authentication | C43: Reset password - cross-account token | D43: Use the account A token with the account B email | E43: Tokens issued for two accounts | F43: 1. POST /reset-password with the A token and the B email | G43: A token plus B email | H43: Rejected - token binding is verified server-side | J43: High | K43: Critical | L43: Security / Negative | M43: Staging - Postman / REST client | N43: Not Executed
A44: AUTH-043 | B44: Authentication | C44: Change password when signed in | D44: Update the password from the account area | E44: Signed-in customer | F44: 1. Open profile security 2. Enter the current and new password 3. Save | G44: current=Passw0rdTest1; new=NewPassw0rd1 | H44: The password changes only when the current password is correct, and a confirmation is shown | J44: High | K44: Major | L44: Functional / Positive | M44: Staging - Chrome 126 (Win 11) | N44: Not Executed
A45: AUTH-044 | B45: Authentication | C45: Change password - wrong current | D45: Update using an incorrect current password | E45: Signed-in customer | F45: 1. Enter a wrong current password with a valid new one 2. Save | G45: current=Wrong123; new=NewPassw0rd1 | H45: Rejected; the stored password is unchanged | J45: High | K45: Critical | L45: Negative / Security | M45: Staging - Chrome 126 (Win 11) | N45: Not Executed
A46: AUTH-045 | B46: Authentication | C46: Social login - Google | D46: Sign in through the Google provider | E46: Google OAuth keys configured under Settings > Social login | F46: 1. Click Continue with Google 2. Complete the consent screen 3. Return through the callback | G46: Google test account | H46: The account is linked or created, the user is signed in, and the email is captured from the provider | J46: Medium | K46: Major | L46: Integration / Positive | M46: Staging - Chrome 126 (Win 11) | N46: Not Executed
...

Sheet Dashboard
B2: EXECUTION DASHBOARD
B3: All figures are live formulas over the Test Cases sheet. Fill in Status there and these update automatically.
B5: OVERALL | I5: BY PRIORITY
B6: Metric | C6: Count | D6: % of Total | I6: Priority | J6: Total | K6: Passed | L6: Failed
B7: Total test cases | C7: =COUNTA('Test Cases'!$A$2:$A$643) -> 0 | D7: =IF($C$7=0,0,C7/$C$7) -> 0 | I7: High | J7: =COUNTIF('Test Cases'!$J$2:$J$643,"High") -> 0 | K7: =_xlfn.COUNTIFS('Test Cases'!$J$2:$J$643,"High",'Test Cases'!$N$2:$N$643,"Pass") -> 0 | L7: =_xlfn.COUNTIFS('Test Cases'!$J$2:$J$643,"High",'Test Cases'!$N$2:$N$643,"Fail") -> 0
B8: Not Executed | C8: =COUNTIF('Test Cases'!$N$2:$N$643,"Not Executed") -> 0 | D8: =IF($C$7=0,0,C8/$C$7) -> 0 | I8: Medium | J8: =COUNTIF('Test Cases'!$J$2:$J$643,"Medium") -> 0 | K8: =_xlfn.COUNTIFS('Test Cases'!$J$2:$J$643,"Medium",'Test Cases'!$N$2:$N$643,"Pass") -> 0 | L8: =_xlfn.COUNTIFS('Test Cases'!$J$2:$J$643,"Medium",'Test Cases'!$N$2:$N$643,"Fail") -> 0
B9: Passed | C9: =COUNTIF('Test Cases'!$N$2:$N$643,"Pass") -> 0 | D9: =IF($C$7=0,0,C9/$C$7) -> 0 | I9: Low | J9: =COUNTIF('Test Cases'!$J$2:$J$643,"Low") -> 0 | K9: =_xlfn.COUNTIFS('Test Cases'!$J$2:$J$643,"Low",'Test Cases'!$N$2:$N$643,"Pass") -> 0 | L9: =_xlfn.COUNTIFS('Test Cases'!$J$2:$J$643,"Low",'Test Cases'!$N$2:$N$643,"Fail") -> 0
B10: Failed | C10: =COUNTIF('Test Cases'!$N$2:$N$643,"Fail") -> 0 | D10: =IF($C$7=0,0,C10/$C$7) -> 0
B11: Blocked | C11: =COUNTIF('Test Cases'!$N$2:$N$643,"Blocked") -> 0 | D11: =IF($C$7=0,0,C11/$C$7) -> 0 | I11: BY SEVERITY
B12: Deferred | C12: =COUNTIF('Test Cases'!$N$2:$N$643,"Deferred") -> 0 | D12: =IF($C$7=0,0,C12/$C$7) -> 0 | I12: Severity | J12: Total | K12: Passed | L12: Failed
B13: Not applicable | C13: =COUNTIF('Test Cases'!$N$2:$N$643,"N-A") -> 0 | D13: =IF($C$7=0,0,C13/$C$7) -> 0 | I13: Blocker | J13: =COUNTIF('Test Cases'!$K$2:$K$643,"Blocker") -> 0 | K13: =_xlfn.COUNTIFS('Test Cases'!$K$2:$K$643,"Blocker",'Test Cases'!$N$2:$N$643,"Pass") -> 0 | L13: =_xlfn.COUNTIFS('Test Cases'!$K$2:$K$643,"Blocker",'Test Cases'!$N$2:$N$643,"Fail") -> 0
B14: Executed | C14: =$C$7-$C$8 -> 0 | D14: =IF($C$7=0,0,C14/$C$7) -> 0 | I14: Critical | J14: =COUNTIF('Test Cases'!$K$2:$K$643,"Critical") -> 0 | K14: =_xlfn.COUNTIFS('Test Cases'!$K$2:$K$643,"Critical",'Test Cases'!$N$2:$N$643,"Pass") -> 0 | L14: =_xlfn.COUNTIFS('Test Cases'!$K$2:$K$643,"Critical",'Test Cases'!$N$2:$N$643,"Fail") -> 0
I15: Major | J15: =COUNTIF('Test Cases'!$K$2:$K$643,"Major") -> 0 | K15: =_xlfn.COUNTIFS('Test Cases'!$K$2:$K$643,"Major",'Test Cases'!$N$2:$N$643,"Pass") -> 0 | L15: =_xlfn.COUNTIFS('Test Cases'!$K$2:$K$643,"Major",'Test Cases'!$N$2:$N$643,"Fail") -> 0
B16: Execution progress | C16: =IF($C$7=0,0,$C$14/$C$7) -> 0 | I16: Minor | J16: =COUNTIF('Test Cases'!$K$2:$K$643,"Minor") -> 0 | K16: =_xlfn.COUNTIFS('Test Cases'!$K$2:$K$643,"Minor",'Test Cases'!$N$2:$N$643,"Pass") -> 0 | L16: =_xlfn.COUNTIFS('Test Cases'!$K$2:$K$643,"Minor",'Test Cases'!$N$2:$N$643,"Fail") -> 0
B17: Pass rate (of executed) | C17: =IF($C$14=0,0,$C$9/$C$14) -> 0
B20: BY MODULE | I20: BY TEST TYPE (primary)
B21: Module | C21: Total | D21: Passed | E21: Failed | F21: Blocked | G21: Not Executed | I21: Test Type | J21: Total | K21: Passed | L21: Failed
B22: API | C22: =COUNTIF('Test Cases'!$B$2:$B$643,"API") -> 0 | D22: =_xlfn.COUNTIFS('Test Cases'!$B$2:$B$643,"API",'Test Cases'!$N$2:$N$643,"Pass") -> 0 | E22: =_xlfn.COUNTIFS('Test Cases'!$B$2:$B$643,"API",'Test Cases'!$N$2:$N$643,"Fail") -> 0 | F22: =_xlfn.COUNTIFS('Test Cases'!$B$2:$B$643,"API",'Test Cases'!$N$2:$N$643,"Blocked") -> 0 | G22: =_xlfn.COUNTIFS('Test Cases'!$B$2:$B$643,"API",'Test Cases'!$N$2:$N$643,"Not Executed") -> 0 | I22: Functional | J22: =COUNTIF('Test Cases'!$L$2:$L$643,"Functional*") -> 0 | K22: =_xlfn.COUNTIFS('Test Cases'!$L$2:$L$643,"Functional*",'Test Cases'!$N$2:$N$643,"Pass") -> 0 | L22: =_xlfn.COUNTIFS('Test Cases'!$L$2:$L$643,"Functional*",'Test Cases'!$N$2:$N$643,"Fail") -> 0
B23: Accessibility | C23: =COUNTIF('Test Cases'!$B$2:$B$643,"Accessibility") -> 0 | D23: =_xlfn.COUNTIFS('Test Cases'!$B$2:$B$643,"Accessibility",'Test Cases'!$N$2:$N$643,"Pass") -> 0 | E23: =_xlfn.COUNTIFS('Test Cases'!$B$2:$B$643,"Accessibility",'Test Cases'!$N$2:$N$643,"Fail") -> 0 | F23: =_xlfn.COUNTIFS('Test Cases'!$B$2:$B$643,"Accessibility",'Test Cases'!$N$2:$N$643,"Blocked") -> 0 | G23: =_xlfn.COUNTIFS('Test Cases'!$B$2:$B$643,"Accessibility",'Test Cases'!$N$2:$N$643,"Not Executed") -> 0 | I23: Security | J23: =COUNTIF('Test Cases'!$L$2:$L$643,"Security*") -> 0 | K23: =_xlfn.COUNTIFS('Test Cases'!$L$2:$L$643,"Security*",'Test Cases'!$N$2:$N$643,"Pass") -> 0 | L23: =_xlfn.COUNTIFS('Test Cases'!$L$2:$L$643,"Security*",'Test Cases'!$N$2:$N$643,"Fail") -> 0
B24: Admin Authentication | C24: =COUNTIF('Test Cases'!$B$2:$B$643,"Admin Authentication") -> 0 | D24: =_xlfn.COUNTIFS('Test Cases'!$B$2:$B$643,"Admin Authentication",'Test Cases'!$N$2:$N$643,"Pass") -> 0 | E24: =_xlfn.COUNTIFS('Test Cases'!$B$2:$B$643,"Admin Authentication",'Test Cases'!$N$2:$N$643,"Fail") -> 0 | F24: =_xlfn.COUNTIFS('Test Cases'!$B$2:$B$643,"Admin Authentication",'Test Cases'!$N$2:$N$643,"Blocked") -> 0 | G24: =_xlfn.COUNTIFS('Test Cases'!$B$2:$B$643,"Admin Authentication",'Test Cases'!$N$2:$N$643,"Not Executed") -> 0 | I24: Negative | J24: =COUNTIF('Test Cases'!$L$2:$L$643,"Negative*") -> 0 | K24: =_xlfn.COUNTIFS('Test Cases'!$L$2:$L$643,"Negative*",'Test Cases'!$N$2:$N$643,"Pass") -> 0 | L24: =_xlfn.COUNTIFS('Test Cases'!$L$2:$L$643,"Negative*",'Test Cases'!$N$2:$N$643,"Fail") -> 0
B25: Authentication | C25: =COUNTIF('Test Cases'!$B$2:$B$643,"Authentication") -> 0 | D25: =_xlfn.COUNTIFS('Test Cases'!$B$2:$B$643,"Authentication",'Test Cases'!$N$2:$N$643,"Pass") -> 0 | E25: =_xlfn.COUNTIFS('Test Cases'!$B$2:$B$643,"Authentication",'Test Cases'!$N$2:$N$643,"Fail") -> 0 | F25: =_xlfn.COUNTIFS('Test Cases'!$B$2:$B$643,"Authentication",'Test Cases'!$N$2:$N$643,"Blocked") -> 0 | G25: =_xlfn.COUNTIFS('Test Cases'!$B$2:$B$643,"Authentication",'Test Cases'!$N$2:$N$643,"Not Executed") -> 0 | I25: Validation | J25: =COUNTIF('Test Cases'!$L$2:$L$643,"Validation*") -> 0 | K25: =_xlfn.COUNTIFS('Test Cases'!$L$2:$L$643,"Validation*",'Test Cases'!$N$2:$N$643,"Pass") -> 0 | L25: =_xlfn.COUNTIFS('Test Cases'!$L$2:$L$643,"Validation*",'Test Cases'!$N$2:$N$643,"Fail") -> 0
B26: Cart | C26: =COUNTIF('Test Cases'!$B$2:$B$643,"Cart") -> 0 | D26: =_xlfn.COUNTIFS('Test Cases'!$B$2:$B$643,"Cart",'Test Cases'!$N$2:$N$643,"Pass") -> 0 | E26: =_xlfn.COUNTIFS('Test Cases'!$B$2:$B$643,"Cart",'Test Cases'!$N$2:$N$643,"Fail") -> 0 | F26: =_xlfn.COUNTIFS('Test Cases'!$B$2:$B$643,"Cart",'Test Cases'!$N$2:$N$643,"Blocked") -> 0 | G26: =_xlfn.COUNTIFS('Test Cases'!$B$2:$B$643,"Cart",'Test Cases'!$N$2:$N$643,"Not Executed") -> 0 | I26: Boundary | J26: =COUNTIF('Test Cases'!$L$2:$L$643,"Boundary*") -> 0 | K26: =_xlfn.COUNTIFS('Test Cases'!$L$2:$L$643,"Boundary*",'Test Cases'!$N$2:$N$643,"Pass") -> 0 | L26: =_xlfn.COUNTIFS('Test Cases'!$L$2:$L$643,"Boundary*",'Test Cases'!$N$2:$N$643,"Fail") -> 0
B27: Catalogue Structure | C27: =COUNTIF('Test Cases'!$B$2:$B$643,"Catalogue Structure") -> 0 | D27: =_xlfn.COUNTIFS('Test Cases'!$B$2:$B$643,"Catalogue Structure",'Test Cases'!$N$2:$N$643,"Pass") -> 0 | E27: =_xlfn.COUNTIFS('Test Cases'!$B$2:$B$643,"Catalogue Structure",'Test Cases'!$N$2:$N$643,"Fail") -> 0 | F27: =_xlfn.COUNTIFS('Test Cases'!$B$2:$B$643,"Catalogue Structure",'Test Cases'!$N$2:$N$643,"Blocked") -> 0 | G27: =_xlfn.COUNTIFS('Test Cases'!$B$2:$B$643,"Catalogue Structure",'Test Cases'!$N$2:$N$643,"Not Executed") -> 0 | I27: Integration | J27: =COUNTIF('Test Cases'!$L$2:$L$643,"Integration*") -> 0 | K27: =_xlfn.COUNTIFS('Test Cases'!$L$2:$L$643,"Integration*",'Test Cases'!$N$2:$N$643,"Pass") -> 0 | L27: =_xlfn.COUNTIFS('Test Cases'!$L$2:$L$643,"Integration*",'Test Cases'!$N$2:$N$643,"Fail") -> 0
B28: Checkout | C28: =COUNTIF('Test Cases'!$B$2:$B$643,"Checkout") -> 0 | D28: =_xlfn.COUNTIFS('Test Cases'!$B$2:$B$643,"Checkout",'Test Cases'!$N$2:$N$643,"Pass") -> 0 | E28: =_xlfn.COUNTIFS('Test Cases'!$B$2:$B$643,"Checkout",'Test Cases'!$N$2:$N$643,"Fail") -> 0 | F28: =_xlfn.COUNTIFS('Test Cases'!$B$2:$B$643,"Checkout",'Test Cases'!$N$2:$N$643,"Blocked") -> 0 | G28: =_xlfn.COUNTIFS('Test Cases'!$B$2:$B$643,"Checkout",'Test Cases'!$N$2:$N$643,"Not Executed") -> 0 | I28: Edge | J28: =COUNTIF('Test Cases'!$L$2:$L$643,"Edge*") -> 0 | K28: =_xlfn.COUNTIFS('Test Cases'!$L$2:$L$643,"Edge*",'Test Cases'!$N$2:$N$643,"Pass") -> 0 | L28: =_xlfn.COUNTIFS('Test Cases'!$L$2:$L$643,"Edge*",'Test Cases'!$N$2:$N$643,"Fail") -> 0
B29: Compatibility | C29: =COUNTIF('Test Cases'!$B$2:$B$643,"Compatibility") -> 0 | D29: =_xlfn.COUNTIFS('Test Cases'!$B$2:$B$643,"Compatibility",'Test Cases'!$N$2:$N$643,"Pass") -> 0 | E29: =_xlfn.COUNTIFS('Test Cases'!$B$2:$B$643,"Compatibility",'Test Cases'!$N$2:$N$643,"Fail") -> 0 | F29: =_xlfn.COUNTIFS('Test Cases'!$B$2:$B$643,"Compatibility",'Test Cases'!$N$2:$N$643,"Blocked") -> 0 | G29: =_xlfn.COUNTIFS('Test Cases'!$B$2:$B$643,"Compatibility",'Test Cases'!$N$2:$N$643,"Not Executed") -> 0 | I29: Data integrity | J29: =COUNTIF('Test Cases'!$L$2:$L$643,"Data integrity*") -> 0 | K29: =_xlfn.COUNTIFS('Test Cases'!$L$2:$L$643,"Data integrity*",'Test Cases'!$N$2:$N$643,"Pass") -> 0 | L29: =_xlfn.COUNTIFS('Test Cases'!$L$2:$L$643,"Data integrity*",'Test Cases'!$N$2:$N$643,"Fail") -> 0
B30: Content Management | C30: =COUNTIF('Test Cases'!$B$2:$B$643,"Content Management") -> 0 | D30: =_xlfn.COUNTIFS('Test Cases'!$B$2:$B$643,"Content Management",'Test Cases'!$N$2:$N$643,"Pass") -> 0 | E30: =_xlfn.COUNTIFS('Test Cases'!$B$2:$B$643,"Content Management",'Test Cases'!$N$2:$N$643,"Fail") -> 0 | F30: =_xlfn.COUNTIFS('Test Cases'!$B$2:$B$643,"Content Management",'Test Cases'!$N$2:$N$643,"Blocked") -> 0 | G30: =_xlfn.COUNTIFS('Test Cases'!$B$2:$B$643,"Content Management",'Test Cases'!$N$2:$N$643,"Not Executed") -> 0 | I30: E2E | J30: =COUNTIF('Test Cases'!$L$2:$L$643,"E2E*") -> 0 | K30: =_xlfn.COUNTIFS('Test Cases'!$L$2:$L$643,"E2E*",'Test Cases'!$N$2:$N$643,"Pass") -> 0 | L30: =_xlfn.COUNTIFS('Test Cases'!$L$2:$L$643,"E2E*",'Test Cases'!$N$2:$N$643,"Fail") -> 0
B31: Customer Account | C31: =COUNTIF('Test Cases'!$B$2:$B$643,"Customer Account") -> 0 | D31: =_xlfn.COUNTIFS('Test Cases'!$B$2:$B$643,"Customer Account",'Test Cases'!$N$2:$N$643,"Pass") -> 0 | E31: =_xlfn.COUNTIFS('Test Cases'!$B$2:$B$643,"Customer Account",'Test Cases'!$N$2:$N$643,"Fail") -> 0 | F31: =_xlfn.COUNTIFS('Test Cases'!$B$2:$B$643,"Customer Account",'Test Cases'!$N$2:$N$643,"Blocked") -> 0 | G31: =_xlfn.COUNTIFS('Test Cases'!$B$2:$B$643,"Customer Account",'Test Cases'!$N$2:$N$643,"Not Executed") -> 0 | I31: Performance | J31: =COUNTIF('Test Cases'!$L$2:$L$643,"Performance*") -> 0 | K31: =_xlfn.COUNTIFS('Test Cases'!$L$2:$L$643,"Performance*",'Test Cases'!$N$2:$N$643,"Pass") -> 0 | L31: =_xlfn.COUNTIFS('Test Cases'!$L$2:$L$643,"Performance*",'Test Cases'!$N$2:$N$643,"Fail") -> 0
B32: Database | C32: =COUNTIF('Test Cases'!$B$2:$B$643,"Database") -> 0 | D32: =_xlfn.COUNTIFS('Test Cases'!$B$2:$B$643,"Database",'Test Cases'!$N$2:$N$643,"Pass") -> 0 | E32: =_xlfn.COUNTIFS('Test Cases'!$B$2:$B$643,"Database",'Test Cases'!$N$2:$N$643,"Fail") -> 0 | F32: =_xlfn.COUNTIFS('Test Cases'!$B$2:$B$643,"Database",'Test Cases'!$N$2:$N$643,"Blocked") -> 0 | G32: =_xlfn.COUNTIFS('Test Cases'!$B$2:$B$643,"Database",'Test Cases'!$N$2:$N$643,"Not Executed") -> 0 | I32: Accessibility | J32: =COUNTIF('Test Cases'!$L$2:$L$643,"Accessibility*") -> 0 | K32: =_xlfn.COUNTIFS('Test Cases'!$L$2:$L$643,"Accessibility*",'Test Cases'!$N$2:$N$643,"Pass") -> 0 | L32: =_xlfn.COUNTIFS('Test Cases'!$L$2:$L$643,"Accessibility*",'Test Cases'!$N$2:$N$643,"Fail") -> 0
B33: End-to-End | C33: =COUNTIF('Test Cases'!$B$2:$B$643,"End-to-End") -> 0 | D33: =_xlfn.COUNTIFS('Test Cases'!$B$2:$B$643,"End-to-End",'Test Cases'!$N$2:$N$643,"Pass") -> 0 | E33: =_xlfn.COUNTIFS('Test Cases'!$B$2:$B$643,"End-to-End",'Test Cases'!$N$2:$N$643,"Fail") -> 0 | F33: =_xlfn.COUNTIFS('Test Cases'!$B$2:$B$643,"End-to-End",'Test Cases'!$N$2:$N$643,"Blocked") -> 0 | G33: =_xlfn.COUNTIFS('Test Cases'!$B$2:$B$643,"End-to-End",'Test Cases'!$N$2:$N$643,"Not Executed") -> 0 | I33: Compatibility | J33: =COUNTIF('Test Cases'!$L$2:$L$643,"Compatibility*") -> 0 | K33: =_xlfn.COUNTIFS('Test Cases'!$L$2:$L$643,"Compatibility*",'Test Cases'!$N$2:$N$643,"Pass") -> 0 | L33: =_xlfn.COUNTIFS('Test Cases'!$L$2:$L$643,"Compatibility*",'Test Cases'!$N$2:$N$643,"Fail") -> 0
B34: Error Handling | C34: =COUNTIF('Test Cases'!$B$2:$B$643,"Error Handling") -> 0 | D34: =_xlfn.COUNTIFS('Test Cases'!$B$2:$B$643,"Error Handling",'Test Cases'!$N$2:$N$643,"Pass") -> 0 | E34: =_xlfn.COUNTIFS('Test Cases'!$B$2:$B$643,"Error Handling",'Test Cases'!$N$2:$N$643,"Fail") -> 0 | F34: =_xlfn.COUNTIFS('Test Cases'!$B$2:$B$643,"Error Handling",'Test Cases'!$N$2:$N$643,"Blocked") -> 0 | G34: =_xlfn.COUNTIFS('Test Cases'!$B$2:$B$643,"Error Handling",'Test Cases'!$N$2:$N$643,"Not Executed") -> 0 | I34: Error handling | J34: =COUNTIF('Test Cases'!$L$2:$L$643,"Error handling*") -> 0 | K34: =_xlfn.COUNTIFS('Test Cases'!$L$2:$L$643,"Error handling*",'Test Cases'!$N$2:$N$643,"Pass") -> 0 | L34: =_xlfn.COUNTIFS('Test Cases'!$L$2:$L$643,"Error handling*",'Test Cases'!$N$2:$N$643,"Fail") -> 0
B35: Installation | C35: =COUNTIF('Test Cases'!$B$2:$B$643,"Installation") -> 0 | D35: =_xlfn.COUNTIFS('Test Cases'!$B$2:$B$643,"Installation",'Test Cases'!$N$2:$N$643,"Pass") -> 0 | E35: =_xlfn.COUNTIFS('Test Cases'!$B$2:$B$643,"Installation",'Test Cases'!$N$2:$N$643,"Fail") -> 0 | F35: =_xlfn.COUNTIFS('Test Cases'!$B$2:$B$643,"Installation",'Test Cases'!$N$2:$N$643,"Blocked") -> 0 | G35: =_xlfn.COUNTIFS('Test Cases'!$B$2:$B$643,"Installation",'Test Cases'!$N$2:$N$643,"Not Executed") -> 0 | I35: Responsive | J35: =COUNTIF('Test Cases'!$L$2:$L$643,"Responsive*") -> 0 | K35: =_xlfn.COUNTIFS('Test Cases'!$L$2:$L$643,"Responsive*",'Test Cases'!$N$2:$N$643,"Pass") -> 0 | L35: =_xlfn.COUNTIFS('Test Cases'!$L$2:$L$643,"Responsive*",'Test Cases'!$N$2:$N$643,"Fail") -> 0
B36: Inventory & Stock | C36: =COUNTIF('Test Cases'!$B$2:$B$643,"Inventory & Stock") -> 0 | D36: =_xlfn.COUNTIFS('Test Cases'!$B$2:$B$643,"Inventory & Stock",'Test Cases'!$N$2:$N$643,"Pass") -> 0 | E36: =_xlfn.COUNTIFS('Test Cases'!$B$2:$B$643,"Inventory & Stock",'Test Cases'!$N$2:$N$643,"Fail") -> 0 | F36: =_xlfn.COUNTIFS('Test Cases'!$B$2:$B$643,"Inventory & Stock",'Test Cases'!$N$2:$N$643,"Blocked") -> 0 | G36: =_xlfn.COUNTIFS('Test Cases'!$B$2:$B$643,"Inventory & Stock",'Test Cases'!$N$2:$N$643,"Not Executed") -> 0 | I36: i18n | J36: =COUNTIF('Test Cases'!$L$2:$L$643,"i18n*") -> 0 | K36: =_xlfn.COUNTIFS('Test Cases'!$L$2:$L$643,"i18n*",'Test Cases'!$N$2:$N$643,"Pass") -> 0 | L36: =_xlfn.COUNTIFS('Test Cases'!$L$2:$L$643,"i18n*",'Test Cases'!$N$2:$N$643,"Fail") -> 0
B37: Localisation | C37: =COUNTIF('Test Cases'!$B$2:$B$643,"Localisation") -> 0 | D37: =_xlfn.COUNTIFS('Test Cases'!$B$2:$B$643,"Localisation",'Test Cases'!$N$2:$N$643,"Pass") -> 0 | E37: =_xlfn.COUNTIFS('Test Cases'!$B$2:$B$643,"Localisation",'Test Cases'!$N$2:$N$643,"Fail") -> 0 | F37: =_xlfn.COUNTIFS('Test Cases'!$B$2:$B$643,"Localisation",'Test Cases'!$N$2:$N$643,"Blocked") -> 0 | G37: =_xlfn.COUNTIFS('Test Cases'!$B$2:$B$643,"Localisation",'Test Cases'!$N$2:$N$643,"Not Executed") -> 0 | I37: UI | J37: =COUNTIF('Test Cases'!$L$2:$L$643,"UI*") -> 0 | K37: =_xlfn.COUNTIFS('Test Cases'!$L$2:$L$643,"UI*",'Test Cases'!$N$2:$N$643,"Pass") -> 0 | L37: =_xlfn.COUNTIFS('Test Cases'!$L$2:$L$643,"UI*",'Test Cases'!$N$2:$N$643,"Fail") -> 0
B38: Order Management | C38: =COUNTIF('Test Cases'!$B$2:$B$643,"Order Management") -> 0 | D38: =_xlfn.COUNTIFS('Test Cases'!$B$2:$B$643,"Order Management",'Test Cases'!$N$2:$N$643,"Pass") -> 0 | E38: =_xlfn.COUNTIFS('Test Cases'!$B$2:$B$643,"Order Management",'Test Cases'!$N$2:$N$643,"Fail") -> 0 | F38: =_xlfn.COUNTIFS('Test Cases'!$B$2:$B$643,"Order Management",'Test Cases'!$N$2:$N$643,"Blocked") -> 0 | G38: =_xlfn.COUNTIFS('Test Cases'!$B$2:$B$643,"Order Management",'Test Cases'!$N$2:$N$643,"Not Executed") -> 0 | I38: Concurrency | J38: =COUNTIF('Test Cases'!$L$2:$L$643,"Concurrency*") -> 0 | K38: =_xlfn.COUNTIFS('Test Cases'!$L$2:$L$643,"Concurrency*",'Test Cases'!$N$2:$N$643,"Pass") -> 0 | L38: =_xlfn.COUNTIFS('Test Cases'!$L$2:$L$643,"Concurrency*",'Test Cases'!$N$2:$N$643,"Fail") -> 0
B39: Payments | C39: =COUNTIF('Test Cases'!$B$2:$B$643,"Payments") -> 0 | D39: =_xlfn.COUNTIFS('Test Cases'!$B$2:$B$643,"Payments",'Test Cases'!$N$2:$N$643,"Pass") -> 0 | E39: =_xlfn.COUNTIFS('Test Cases'!$B$2:$B$643,"Payments",'Test Cases'!$N$2:$N$643,"Fail") -> 0 | F39: =_xlfn.COUNTIFS('Test Cases'!$B$2:$B$643,"Payments",'Test Cases'!$N$2:$N$643,"Blocked") -> 0 | G39: =_xlfn.COUNTIFS('Test Cases'!$B$2:$B$643,"Payments",'Test Cases'!$N$2:$N$643,"Not Executed") -> 0 | I39: Recovery | J39: =COUNTIF('Test Cases'!$L$2:$L$643,"Recovery*") -> 0 | K39: =_xlfn.COUNTIFS('Test Cases'!$L$2:$L$643,"Recovery*",'Test Cases'!$N$2:$N$643,"Pass") -> 0 | L39: =_xlfn.COUNTIFS('Test Cases'!$L$2:$L$643,"Recovery*",'Test Cases'!$N$2:$N$643,"Fail") -> 0
B40: Performance | C40: =COUNTIF('Test Cases'!$B$2:$B$643,"Performance") -> 0 | D40: =_xlfn.COUNTIFS('Test Cases'!$B$2:$B$643,"Performance",'Test Cases'!$N$2:$N$643,"Pass") -> 0 | E40: =_xlfn.COUNTIFS('Test Cases'!$B$2:$B$643,"Performance",'Test Cases'!$N$2:$N$643,"Fail") -> 0 | F40: =_xlfn.COUNTIFS('Test Cases'!$B$2:$B$643,"Performance",'Test Cases'!$N$2:$N$643,"Blocked") -> 0 | G40: =_xlfn.COUNTIFS('Test Cases'!$B$2:$B$643,"Performance",'Test Cases'!$N$2:$N$643,"Not Executed") -> 0 | I40: Deployment | J40: =COUNTIF('Test Cases'!$L$2:$L$643,"Deployment*") -> 0 | K40: =_xlfn.COUNTIFS('Test Cases'!$L$2:$L$643,"Deployment*",'Test Cases'!$N$2:$N$643,"Pass") -> 0 | L40: =_xlfn.COUNTIFS('Test Cases'!$L$2:$L$643,"Deployment*",'Test Cases'!$N$2:$N$643,"Fail") -> 0
B41: Point of Sale | C41: =COUNTIF('Test Cases'!$B$2:$B$643,"Point of Sale") -> 0 | D41: =_xlfn.COUNTIFS('Test Cases'!$B$2:$B$643,"Point of Sale",'Test Cases'!$N$2:$N$643,"Pass") -> 0 | E41: =_xlfn.COUNTIFS('Test Cases'!$B$2:$B$643,"Point of Sale",'Test Cases'!$N$2:$N$643,"Fail") -> 0 | F41: =_xlfn.COUNTIFS('Test Cases'!$B$2:$B$643,"Point of Sale",'Test Cases'!$N$2:$N$643,"Blocked") -> 0 | G41: =_xlfn.COUNTIFS('Test Cases'!$B$2:$B$643,"Point of Sale",'Test Cases'!$N$2:$N$643,"Not Executed") -> 0 | I41: TOTAL | J41: =SUM(J$22:J$40) -> 0 | K41: =SUM(K$22:K$40) -> 0 | L41: =SUM(L$22:L$40) -> 0
B42: Pricing & Promotions | C42: =COUNTIF('Test Cases'!$B$2:$B$643,"Pricing & Promotions") -> 0 | D42: =_xlfn.COUNTIFS('Test Cases'!$B$2:$B$643,"Pricing & Promotions",'Test Cases'!$N$2:$N$643,"Pass") -> 0 | E42: =_xlfn.COUNTIFS('Test Cases'!$B$2:$B$643,"Pricing & Promotions",'Test Cases'!$N$2:$N$643,"Fail") -> 0 | F42: =_xlfn.COUNTIFS('Test Cases'!$B$2:$B$643,"Pricing & Promotions",'Test Cases'!$N$2:$N$643,"Blocked") -> 0 | G42: =_xlfn.COUNTIFS('Test Cases'!$B$2:$B$643,"Pricing & Promotions",'Test Cases'!$N$2:$N$643,"Not Executed") -> 0
B43: Procurement | C43: =COUNTIF('Test Cases'!$B$2:$B$643,"Procurement") -> 0 | D43: =_xlfn.COUNTIFS('Test Cases'!$B$2:$B$643,"Procurement",'Test Cases'!$N$2:$N$643,"Pass") -> 0 | E43: =_xlfn.COUNTIFS('Test Cases'!$B$2:$B$643,"Procurement",'Test Cases'!$N$2:$N$643,"Fail") -> 0 | F43: =_xlfn.COUNTIFS('Test Cases'!$B$2:$B$643,"Procurement",'Test Cases'!$N$2:$N$643,"Blocked") -> 0 | G43: =_xlfn.COUNTIFS('Test Cases'!$B$2:$B$643,"Procurement",'Test Cases'!$N$2:$N$643,"Not Executed") -> 0
B44: Product Management | C44: =COUNTIF('Test Cases'!$B$2:$B$643,"Product Management") -> 0 | D44: =_xlfn.COUNTIFS('Test Cases'!$B$2:$B$643,"Product Management",'Test Cases'!$N$2:$N$643,"Pass") -> 0 | E44: =_xlfn.COUNTIFS('Test Cases'!$B$2:$B$643,"Product Management",'Test Cases'!$N$2:$N$643,"Fail") -> 0 | F44: =_xlfn.COUNTIFS('Test Cases'!$B$2:$B$643,"Product Management",'Test Cases'!$N$2:$N$643,"Blocked") -> 0 | G44: =_xlfn.COUNTIFS('Test Cases'!$B$2:$B$643,"Product Management",'Test Cases'!$N$2:$N$643,"Not Executed") -> 0
...

Sheet Traceability
A1: Module | B1: ID Prefix | C1: Test Cases | D1: High Priority | E1: Blocker + Critical | F1: Primary Application Area | G1: Key Risk Focus
A2: API | B2: API | C2: 14 | D2: 1 | E2: 1 | F2: routes/api.php contract surface | G2: Response consistency, status codes, type handling, concurrency
A3: Accessibility | B3: A11Y | C3: 12 | D3: 3 | E3: 0 | F3: Cross-cutting - storefront and admin | G3: Keyboard operation, labels, contrast, screen reader journeys
A4: Admin Authentication | B4: ADM | C4: 10 | D4: 5 | E4: 4 | F4: AdminsController, admin-panel/pages/login.vue | G4: Unauthenticated admin creation, session handling, direct URL access
A5: Authentication | B5: AUTH | C5: 60 | D5: 38 | E5: 22 | F5: app/Http/Controllers/UsersController.php, TwoFactorController, routes/api.php user group | G5: Account takeover, code brute force, enumeration, guest token forgery, scope enforcement
A6: Cart | B6: CART | C6: 27 | D6: 15 | E6: 11 | F6: CartsController, SaveForLaterController, UserWishlistsController, CompareListsController | G6: Client-supplied prices, quantity bounds, IDOR on cart rows, buy-now scope
A7: Catalogue Structure | B7: CAT | C7: 24 | D7: 10 | E7: 3 | F7: CategoriesController, SubCategoriesController, BrandsController, AttributesController | G7: Slug integrity, cascade deletes, image upload safety, stored XSS
A8: Checkout | B8: CHK | C8: 26 | D8: 13 | E8: 10 | F8: OrdersController, Validation::order, frontend-panel/pages/checkout.vue | G8: Payload tampering, guest path, double submit, stock re-check, confirmation email
A9: Compatibility | B9: COMP | C9: 12 | D9: 5 | E9: 0 | F9: Cross-cutting - browsers, devices, email clients | G9: Rendering parity, blockers, degraded modes
A10: Content Management | B10: CMS | C10: 20 | D10: 1 | E10: 2 | F10: PagesController, BannersController, HomeSlidersController, CustomScriptsController | G10: Editor sanitisation, upload validation, stored script feature control
A11: Customer Account | B11: USR | C11: 18 | D11: 4 | E11: 4 | F11: UsersController, UserAddressesController, ContactUsController | G11: Profile and address IDOR, email change verification, data retention
A12: Database | B12: DB | C12: 12 | D12: 8 | E12: 8 | F12: database/migrations, models and relations | G12: Referential integrity, atomicity, monetary precision, reconciliation
A13: End-to-End | B13: E2E | C13: 14 | D13: 11 | E13: 10 | F13: Full stack across all modules | G13: Journey completeness and money, stock and notification reconciliation
... A34: Wallet & Loyalty | B34: WAL | C34: 18 | D34: 13 | E34: 12 | F34: WalletController, WalletOverviewController, LoyaltyGroupController | G34: Balance integrity, unauthenticated access, points timing, concurrent spend
A35: TOTAL | C35: =SUM(C2:C34) -> 0 | D35: =SUM(D2:D34) -> 0 | E35: =SUM(E2:E34) -> 0

Sheet Defect Log
A1: Defect ID | B1: Test Case ID | C1: Module | D1: Summary | E1: Steps to Reproduce | F1: Expected | G1: Actual | H1: Severity | I1: Priority | J1: Environment | K1: Reported By | L1: Reported On | M1: Assigned To | N1: Status | O1: Fixed In Build | P1: Retest Result | Q1: Remarks
A2: DEF-001 | D2: Example row - delete before use. One defect per row; always reference the Test Case ID it came from.

Sheet Test Data
A1: Category | B1: Item | C1: Value / Detail | D1: Notes
A2: Accounts | B2: Superadmin | C2: admin@fixmypc.test / Admin@12345 | D2: Full permissions. Used for every admin-only case.
A3: Accounts | B3: Limited admin (Catalogue Editor) | C3: qa.editor@fixmypc.test / Editor@12345 | D3: Product permissions only. Used for permission-enforcement cases.
A4: Accounts | B4: Vendor A | C4: vendor.a@fixmypc.test / Vendor@12345 | D4: Approved vendor with products, orders and a payout balance.
A5: Accounts | B5: Vendor B | C5: vendor.b@fixmypc.test / Vendor@12345 | D5: Second vendor - the counterparty for cross-vendor isolation cases.
A6: Accounts | B6: Customer A (personal) | C6: qa.personal01@example.com / Passw0rdTest1 | D6: Verified, has order history, saved addresses, wallet balance and points.
A7: Accounts | B7: Customer B (personal) | C7: qa.personal02@example.com / Passw0rdTest1 | D7: The counterparty for every IDOR case - never share resources with A.
A8: Accounts | B8: Customer (business) | C8: qa.business01@example.com / Passw0rdTest1 | D8: Approved business account with a company profile.
A9: Accounts | B9: Customer (trade) | C9: qa.trade01@example.com / Passw0rdTest1 | D9: Approved trade account - used for trade pricing cases.
A10: Accounts | B10: Unverified customer | C10: qa.unverified@example.com / Passw0rdTest1 | D10: Registered but never verified. Do not verify it.
A11: Accounts | B11: Deactivated customer | C11: qa.disabled@example.com / Passw0rdTest1 | D11: Set to inactive. Used for blocked-login cases.
A12: Accounts | B12: 2FA-enabled customer | C12: qa.twofactor@example.com / Passw0rdTest1 | D12: TOTP configured. Keep the seed with the QA lead.
... A55: Boundaries | B55: Awkward money values | C55: 0.01, 19.99, 1234.56, 999999.99 | D55: Precision and rounding checks.

Sheet Environments
A1: Environment Label | B1: Type | C1: Operating System | D1: Browser / Client | E1: Viewport / Device | F1: Purpose
A2: Staging - Chrome 126 (Win 11) | B2: Web UI | C2: Windows 11 | D2: Chrome 126 | E2: 1920x1080 | F2: Primary execution environment for functional, UI and validation cases.
A3: Staging - Postman / REST client | B3: API | C3: Any | D3: Postman / curl | E3: n/a | F3: Direct API cases - security, contract, IDOR and concurrency.
A4: Staging - iOS Safari 17 + Android Chrome 126 | B4: Web UI (mobile) | C4: iOS 17 / Android 13 | D4: Safari 17 / Chrome 126 | E4: iPhone 13, Pixel 6 | F4: Responsive, mobile end-to-end and PWA cases.
A5: Staging - MySQL 8 / phpMyAdmin | B5: Database | C5: Linux | D5: phpMyAdmin / CLI | E5: n/a | F5: Data integrity, reconciliation, migration and backup cases.
A6: Staging - Firefox 127 | B6: Web UI | C6: Windows 11 | D6: Firefox 127 | E6: 1920x1080 | F6: Cross-browser compatibility pass.
A7: Staging - Safari 17 (macOS) | B7: Web UI | C7: macOS Sonoma | D7: Safari 17 | E7: 1440x900 | F7: Cross-browser compatibility pass, payment sheet behaviour.
A8: Staging - Edge 126 | B8: Web UI | C8: Windows 11 | D8: Edge 126 | E8: 1920x1080 | F8: Cross-browser compatibility pass.
A9: Staging - Tablet | B9: Web UI | C9: iPadOS 17 | D9: Safari 17 | E9: 768x1024 | F9: Tablet breakpoint and admin-on-tablet cases.
A10: Staging - Load harness | B10: Performance | C10: Linux | D10: k6 / JMeter | E10: n/a | F10: Load, soak and concurrency cases.
A11: Staging - Assistive tech | B11: Accessibility | C11: Windows 11 / macOS | D11: NVDA / VoiceOver | E11: 1920x1080 | F11: Screen reader and keyboard-only cases.
A12: Pre-production | B12: Full stack | C12: Production parity | D12: Chrome 126 | E12: 1920x1080 | F12: Release-candidate smoke and end-to-end regression only.
A15: ENTRY AND EXIT CRITERIA
A16: Entry criteria | B16: The build is deployed to staging, seed data is loaded, all gateways are in test mode, and the smoke suite E2E-014 passes.
A17: Exit criteria | B17: Every High priority case is executed; no Blocker or Critical defect is open; at least 95% of executed cases pass; all remaining defects are triaged and accepted by the product owner.
A18: Suspension criteria | B18: The smoke suite fails, the environment is unavailable for more than half a day, or a Blocker defect prevents more than 30% of the suite from running.
A19: Resumption criteria | B19: The blocking defect is fixed and verified, and the smoke suite passes again.
A20: Execution order | B20: Run the QA-audit regression cases first (those citing an audit reference in Remarks), then all remaining High priority cases, then Medium, then Low.
