Workbook

Sheet Cover
B2: FixMyPC - Business & Trade Account QA
B3: Personal, Business and Trade accounts: registration, entitlement, pricing, basket, tax, decision emails, admin workflow, state transitions and security.
B6: Document | C6: Business & Trade QA test cases v1.0
B7: Companion to | C7: reference/qa/FixMyPC-Test-Cases-v1.0.xlsx (same columns and vocabulary)
B8: Run date | C8: 14 Sep 2026
B9: Executed by | C9: Automated QA pass (tests/Feature/ManualQaSuiteTest.php)
B10: Environment | C10: Local - Laravel HTTP kernel via PHPUnit, MySQL 8, array mail transport
B12: Total test cases | C12: 223
B13: Executed | C13: 214
B14: Passed | C14: 214
B15: Failed | C15: 0
B16: Blocked | C16: 9
B17: Pass rate (of executed) | C17: 100%
B19: How results were obtained | C19: Each case runs against the real application and database inside a transaction that is rolled back, and asserts the backend result - the stored row, the API payload, the entitlement method the pricing path calls, or the rendered email. Not a screen check.
B20: Suite validity | C20: Two deliberate regressions were introduced and the run repeated, to confirm the cases can fail: removing the suspension check from User::hasBusinessPricing() was caught by 4 cases, removing the duplicate-email guard by 2. Both were reverted.
B21: Severity mapping | C21: The run records Critical/High/Medium/Low. This workbook splits that across the master template vocabulary: Severity is Blocker/Critical/Major/Minor and Priority is High/Medium/Low, so the Dashboard formulas count correctly.
B22: Not signed off | C22: Payment, order and invoice (PAY-01, PAY-02, ORD-01, INV-01) could not be executed. Two are Critical. See the Blocked Items sheet.

Sheet Test Cases
A1: Test Case ID | B1: Module | C1: Feature / Functionality | D1: Test Scenario | E1: Preconditions | F1: Test Steps | G1: Test Data | H1: Expected Result | I1: Actual Result | J1: Priority | K1: Severity | L1: Test Type | M1: Environment | N1: Status | O1: Remarks
A2: AT-PER-01 | B2: Account type | C2: Account type selection and integrity | D2: Personal account type is stored as chosen | E2: No account on the address | F2: POST /api/v1/user/signup with a complete payload for the type | G2: account_type=personal | H2: users.account_type = personal | I2: account_type=personal | J2: High | K2: Major | L2: Functional / Positive | M2: Local - PHPUnit / Laravel HTTP kernel + MySQL 8 | N2: Pass
A3: AT-BUS-01 | B3: Account type | C3: Account type selection and integrity | D3: Business account type is stored as chosen | E3: No account on the address | F3: POST /api/v1/user/signup with a complete payload for the type | G3: account_type=business | H3: users.account_type = business | I3: account_type=business | J3: High | K3: Major | L3: Functional / Positive | M3: Local - PHPUnit / Laravel HTTP kernel + MySQL 8 | N3: Pass
A4: AT-TRA-01 | B4: Account type | C4: Account type selection and integrity | D4: Trade account type is stored as chosen | E4: No account on the address | F4: POST /api/v1/user/signup with a complete payload for the type | G4: account_type=trade | H4: users.account_type = trade | I4: account_type=trade | J4: High | K4: Major | L4: Functional / Positive | M4: Local - PHPUnit / Laravel HTTP kernel + MySQL 8 | N4: Pass
A5: AT-DEF-01 | B5: Account type | C5: Account type selection and integrity | D5: Signup with no account_type defaults to Personal | E5: Legacy caller that sends no account_type | F5: POST /api/v1/user/signup omitting account_type | G5: name, email, password only | H5: Account created as personal, legacy validation used | I5: account_type=personal | J5: Medium | K5: Minor | L5: Functional / Positive | M5: Local - PHPUnit / Laravel HTTP kernel + MySQL 8 | N5: Pass
A6: AT-INV-01 | B6: Account type | C6: Account type selection and integrity | D6: Unknown account_type is refused, not silently defaulted | E6: None | F6: POST /api/v1/user/signup with an invented type | G6: account_type='wholesale' | H6: Validation error on account_type; no account created | I6: status=201 fields=account_type created=no | J6: High | K6: Major | L6: Validation / Negative | M6: Local - PHPUnit / Laravel HTTP kernel + MySQL 8 | N6: Pass
A7: AT-INV-02 | B7: Account type | C7: Account type selection and integrity | D7: Array injected as account_type does not crash or elevate | E7: None | F7: POST signup with an array account_type | G7: account_type=["trade"] | H7: Refused cleanly, no account, no 500 | I7: http=200 status=201 | J7: High | K7: Major | L7: Validation / Negative | M7: Local - PHPUnit / Laravel HTTP kernel + MySQL 8 | N7: Pass
A8: AT-SEC-01 | B8: Account type | C8: Account type selection and integrity | D8: Signup cannot self-approve trade or self-verify | E8: None | F8: POST signup for a trade account with privileged fields injected | G8: trade_status=approved, verified=1, verification_status=verified | H8: trade_status=pending, verified=0, verification=pending, not entitled | I8: trade_status=pending verified=0 verification=pending entitled=no | J8: High | K8: Critical | L8: Validation / Negative | M8: Local - PHPUnit / Laravel HTTP kernel + MySQL 8 | N8: Pass
A9: AT-SEC-02 | B9: Account type | C9: Account type selection and integrity | D9: Personal signup carrying stale trade fields creates no trade profile | E9: Customer switched Trade -> Personal before submitting; form posts whole model | F9: POST signup as personal with the trade block still attached | G9: account_type=personal + company_name, trade, vat_number, resale_confirmed | H9: personal account, no user_business_profiles row, trade_status null | I9: type=personal trade_status=NULL profile=none | J9: High | K9: Major | L9: Functional / Positive | M9: Local - PHPUnit / Laravel HTTP kernel + MySQL 8 | N9: Pass
A10: AT-SEC-03 | B10: Account type | C10: Account type selection and integrity | D10: Trade signup does not persist business-only fields | E10: Customer switched Business -> Trade, business fields still posted | F10: POST signup as trade with the business block attached | G10: account_type=trade + sector, requires_po, credit_application | H10: sector null; requires_po and credit_application false | I10: sector=NULL requires_po=false credit=false | J10: Medium | K10: Minor | L10: Validation / Negative | M10: Local - PHPUnit / Laravel HTTP kernel + MySQL 8 | N10: Pass
A11: AT-SEC-04 | B11: Account type | C11: Account type selection and integrity | D11: Signed-in customer cannot change their own account type | E11: Active personal account | F11: Authenticate as customer, POST /api/v1/user/update-profile | G11: update-profile with account_type=business, trade_status=approved | H11: account_type unchanged, not entitled to business pricing | I11: type=personal entitled=no | J11: High | K11: Critical | L11: Validation / Negative | M11: Local - PHPUnit / Laravel HTTP kernel + MySQL 8 | N11: Pass
A12: REG-B-01 | B12: Business registration | C12: Business account registration | D12: Valid business registration | E12: No account on the address | F12: POST /api/v1/user/signup | G12: complete valid payload | H12: Accepted; account created with the right type | I12: status=200 fields= created=business | J12: High | K12: Major | L12: Functional / Positive | M12: Local - PHPUnit / Laravel HTTP kernel + MySQL 8 | N12: Pass
A13: REG-B-02 | B13: Business registration | C13: Business account registration | D13: Business with no company name | E13: No account on the address | F13: POST /api/v1/user/signup | G13: {"company_name":""} | H13: Rejected with a validation error on 'company_name'; no account created | I13: status=201 fields=company_name created=no | J13: High | K13: Major | L13: Validation / Negative | M13: Local - PHPUnit / Laravel HTTP kernel + MySQL 8 | N13: Pass
... A39: REG-E-03 | B39: Registration edge cases | C39: Registration duplicates and re-registration | D39: Duplicate phone on a verified account is refused | E39: A verified account already holds the number | F39: POST business signup with that phone | G39: Existing verified phone | H39: Validation error on phone | I39: fields=phone | J39: Medium | K39: Minor | L39: Validation / Negative | M39: Local - PHPUnit / Laravel HTTP kernel + MySQL 8 | N39: Pass
A40: REG-E-04 | B40: Registration edge cases | C40: Registration duplicates and re-registration | D40: Re-registering an unverified address overwrites it rather than duplicating | E40: An unverified signup exists on the address | F40: POST business signup, then POST trade signup on the same address | G40: Same email, this time as trade | H40: One user row, now trade, still unverified | I40: rows=1 type=trade verified=0 | J40: Medium | K40: Minor | L40: Functional / Positive | M40: Local - PHPUnit / Laravel HTTP kernel + MySQL 8 | N40: Pass | O40: This is how somebody who lost their code starts again.
A41: REG-E-05 | B41: Registration edge cases | C41: Registration duplicates and re-registration | D41: Suspended account cannot be laundered by re-registering | E41: Unverified account on the address, status suspended | F41: POST business signup on the suspended address | G41: Same email | H41: Refused; status stays suspended | I41: status=201 account_status=suspended | J41: High | K41: Critical | L41: Validation / Negative | M41: Local - PHPUnit / Laravel HTTP kernel + MySQL 8 | N41: Pass
A42: REG-E-06 | B42: Registration edge cases | C42: Registration duplicates and re-registration | D42: Double-clicked submit creates one account, not two | E42: None | F42: POST signup twice with the same payload | G42: Identical business payload posted twice | H42: Exactly one users row | I42: user rows=1 | J42: High | K42: Major | L42: Validation / Negative | M42: Local - PHPUnit / Laravel HTTP kernel + MySQL 8 | N42: Pass
A43: REG-H-01 | B43: Business registration | C43: Business account registration | D43: Very long company name | E43: None | F43: POST /api/v1/user/signup as business | G43: {"company_name":"AAAAAAAAAAAAAAAAAAAAAAAAAAAAAAAAAAAAAAAAAAAAAAAAAAAAAAAAA..."} | H43: Either accepted and stored without corruption, or rejected cleanly. No 500. | I43: accepted; stored company_name=NULL | J43: Low | K43: Minor | L43: Boundary / Negative | M43: Local - PHPUnit / Laravel HTTP kernel + MySQL 8 | N43: Pass
A44: REG-H-02 | B44: Business registration | C44: Business account registration | D44: Company name with special characters | E44: None | F44: POST /api/v1/user/signup as business | G44: {"company_name":"O'Brien & Sons (Kilcock) Ltd \u2014 #1"} | H44: Either accepted and stored without corruption, or rejected cleanly. No 500. | I44: accepted; stored company_name='O\'Brien & Sons (Kilcock) Ltd — #1' | J44: Low | K44: Minor | L44: Boundary / Negative | M44: Local - PHPUnit / Laravel HTTP kernel + MySQL 8 | N44: Pass
A45: REG-H-03 | B45: Business registration | C45: Business account registration | D45: Leading and trailing spaces on company name | E45: None | F45: POST /api/v1/user/signup as business | G45: {"company_name":" Spaced Ltd "} | H45: Either accepted and stored without corruption, or rejected cleanly. No 500. | I45: accepted; stored company_name='Spaced Ltd' | J45: Low | K45: Minor | L45: Boundary / Negative | M45: Local - PHPUnit / Laravel HTTP kernel + MySQL 8 | N45: Pass
A46: REG-H-04 | B46: Business registration | C46: Business account registration | D46: Unicode company name | E46: None | F46: POST /api/v1/user/signup as business | G46: {"company_name":"\u00d3 Briain Teoranta \u65e5\u672c"} | H46: Either accepted and stored without corruption, or rejected cleanly. No 500. | I46: accepted; stored company_name='Ó Briain Teoranta 日本' | J46: Low | K46: Minor | L46: Boundary / Negative | M46: Local - PHPUnit / Laravel HTTP kernel + MySQL 8 | N46: Pass
A47: REG-H-05 | B47: Business registration | C47: Business account registration | D47: HTML injected into company name | E47: None | F47: POST /api/v1/user/signup as business | G47: {"company_name":"<script>alert(1)<\/script>"} | H47: Either accepted and stored without corruption, or rejected cleanly. No 500. | I47: accepted; stored company_name='<script>alert(1)</script>' | J47: Medium | K47: Minor | L47: Security / XSS | M47: Local - PHPUnit / Laravel HTTP kernel + MySQL 8 | N47: Pass
A48: REG-H-06 | B48: Business registration | C48: Business account registration | D48: Very long billing address | E48: None | F48: POST /api/v1/user/signup as business | G48: {"billing_address":"AAAAAAAAAAAAAAAAAAAAAAAAAAAAAAAAAAAAAAAAAAAAAAAAAAAAAAAAA..."} | H48: Either accepted and stored without corruption, or rejected cleanly. No 500. | I48: accepted; stored company_name='QA Supplies Ltd' | J48: Low | K48: Minor | L48: Boundary / Negative | M48: Local - PHPUnit / Laravel HTTP kernel + MySQL 8 | N48: Pass
A49: REG-H-07 | B49: Business registration | C49: Business account registration | D49: Whitespace-only company name is not accepted as a name | E49: None | F49: POST signup as business | G49: company_name=' ' | H49: Rejected on company_name | I49: fields=company_name | J49: Medium | K49: Minor | L49: Boundary / Negative | M49: Local - PHPUnit / Laravel HTTP kernel + MySQL 8 | N49: Pass | O49: TrimStrings middleware should reduce this to empty and required should fire.
A50: REG-H-08 | B50: Business registration | C50: Business account registration | D50: Email with surrounding whitespace is normalised, not rejected | E50: None | F50: POST signup as business | G50: email=' name@example.test ' | H50: Accepted, stored trimmed | I50: status=200 stored=yes | J50: Low | K50: Minor | L50: Boundary / Negative | M50: Local - PHPUnit / Laravel HTTP kernel + MySQL 8 | N50: Pass
A51: PRC-ENT-184D | B51: Pricing | C51: Account-based product pricing | D51: Entitlement flag for Personal | E51: Customer in state: Personal | F51: Read the entitlement the whole pricing path asks | G51: User::hasBusinessPricing() | H51: false | I51: hasBusinessPricing=false | J51: High | K51: Critical | L51: Functional / Positive | M51: Local - PHPUnit / Laravel HTTP kernel + MySQL 8 | N51: Pass
A52: PRC-PDP-184D | B52: Pricing | C52: Account-based product pricing | D52: Product page price for Personal | E52: Customer in state: Personal; product has bands from qty 5 | F52: GET /api/v1/product/{id} authenticated as the customer | G52: product=99240288, quantity 1 | H52: Retail price, because no band covers quantity 1 | I52: display_price=505 (retail 505) | J52: High | K52: Major | L52: Functional / Positive | M52: Local - PHPUnit / Laravel HTTP kernel + MySQL 8 | N52: Pass | O52: Bands on this product start at qty 5, so every account sees retail at qty 1.
A53: PRC-CART-184D | B53: Pricing | C53: Account-based product pricing | D53: Basket unit price at qty 5 for Personal | E53: Customer in state: Personal | F53: Create a basket line at qty 5, GET /api/v1/cart/by-user | G53: product=99240288, quantity 5 (band 5-10 = 450.00) | H53: 505 | I53: unit_price=505.0 (expected 505) | J53: High | K53: Critical | L53: Functional / Positive | M53: Local - PHPUnit / Laravel HTTP kernel + MySQL 8 | N53: Pass
A54: PRC-BAND-184D | B54: Pricing | C54: Account-based product pricing | D54: Advertised bands for Personal | E54: Customer in state: Personal | F54: Read the band table the product page renders | G54: GET /api/v1/business-product/99240288 | H54: Empty list | I54: bands=0 | J54: High | K54: Major | L54: Functional / Positive | M54: Local - PHPUnit / Laravel HTTP kernel + MySQL 8 | N54: Pass
A55: PRC-ENT-D6E6 | B55: Pricing | C55: Account-based product pricing | D55: Entitlement flag for Business | E55: Customer in state: Business | F55: Read the entitlement the whole pricing path asks | G55: User::hasBusinessPricing() | H55: true | I55: hasBusinessPricing=true | J55: High | K55: Critical | L55: Functional / Positive | M55: Local - PHPUnit / Laravel HTTP kernel + MySQL 8 | N55: Pass
A56: PRC-PDP-D6E6 | B56: Pricing | C56: Account-based product pricing | D56: Product page price for Business | E56: Customer in state: Business; product has bands from qty 5 | F56: GET /api/v1/product/{id} authenticated as the customer | G56: product=99240288, quantity 1 | H56: Retail price, because no band covers quantity 1 | I56: display_price=505 (retail 505) | J56: High | K56: Major | L56: Functional / Positive | M56: Local - PHPUnit / Laravel HTTP kernel + MySQL 8 | N56: Pass | O56: Bands on this product start at qty 5, so every account sees retail at qty 1.
A57: PRC-CART-D6E6 | B57: Pricing | C57: Account-based product pricing | D57: Basket unit price at qty 5 for Business | E57: Customer in state: Business | F57: Create a basket line at qty 5, GET /api/v1/cart/by-user | G57: product=99240288, quantity 5 (band 5-10 = 450.00) | H57: 450.00 | I57: unit_price=450.0 (expected 450) | J57: High | K57: Critical | L57: Functional / Positive | M57: Local - PHPUnit / Laravel HTTP kernel + MySQL 8 | N57: Pass
A58: PRC-BAND-D6E6 | B58: Pricing | C58: Account-based product pricing | D58: Advertised bands for Business | E58: Customer in state: Business | F58: Read the band table the product page renders | G58: GET /api/v1/business-product/99240288 | H58: Bands returned | I58: bands=3 | J58: High | K58: Major | L58: Functional / Positive | M58: Local - PHPUnit / Laravel HTTP kernel + MySQL 8 | N58: Pass
A59: PRC-ENT-13CE | B59: Pricing | C59: Account-based product pricing | D59: Entitlement flag for Trade pending | E59: Customer in state: Trade pending | F59: Read the entitlement the whole pricing path asks | G59: User::hasBusinessPricing() | H59: false | I59: hasBusinessPricing=false | J59: High | K59: Critical | L59: Functional / Positive | M59: Local - PHPUnit / Laravel HTTP kernel + MySQL 8 | N59: Pass
A60: PRC-PDP-13CE | B60: Pricing | C60: Account-based product pricing | D60: Product page price for Trade pending | E60: Customer in state: Trade pending; product has bands from qty 5 | F60: GET /api/v1/product/{id} authenticated as the customer | G60: product=99240288, quantity 1 | H60: Retail price, because no band covers quantity 1 | I60: display_price=505 (retail 505) | J60: High | K60: Major | L60: Functional / Positive | M60: Local - PHPUnit / Laravel HTTP kernel + MySQL 8 | N60: Pass | O60: Bands on this product start at qty 5, so every account sees retail at qty 1.
A61: PRC-CART-13CE | B61: Pricing | C61: Account-based product pricing | D61: Basket unit price at qty 5 for Trade pending | E61: Customer in state: Trade pending | F61: Create a basket line at qty 5, GET /api/v1/cart/by-user | G61: product=99240288, quantity 5 (band 5-10 = 450.00) | H61: 505 | I61: unit_price=505.0 (expected 505) | J61: High | K61: Critical | L61: Functional / Positive | M61: Local - PHPUnit / Laravel HTTP kernel + MySQL 8 | N61: Pass
A62: PRC-BAND-13CE | B62: Pricing | C62: Account-based product pricing | D62: Advertised bands for Trade pending | E62: Customer in state: Trade pending | F62: Read the band table the product page renders | G62: GET /api/v1/business-product/99240288 | H62: Empty list | I62: bands=0 | J62: High | K62: Major | L62: Functional / Positive | M62: Local - PHPUnit / Laravel HTTP kernel + MySQL 8 | N62: Pass
A63: PRC-ENT-8D2A | B63: Pricing | C63: Account-based product pricing | D63: Entitlement flag for Trade approved | E63: Customer in state: Trade approved | F63: Read the entitlement the whole pricing path asks | G63: User::hasBusinessPricing() | H63: true | I63: hasBusinessPricing=true | J63: High | K63: Critical | L63: Functional / Positive | M63: Local - PHPUnit / Laravel HTTP kernel + MySQL 8 | N63: Pass
A64: PRC-PDP-8D2A | B64: Pricing | C64: Account-based product pricing | D64: Product page price for Trade approved | E64: Customer in state: Trade approved; product has bands from qty 5 | F64: GET /api/v1/product/{id} authenticated as the customer | G64: product=99240288, quantity 1 | H64: Retail price, because no band covers quantity 1 | I64: display_price=505 (retail 505) | J64: High | K64: Major | L64: Functional / Positive | M64: Local - PHPUnit / Laravel HTTP kernel + MySQL 8 | N64: Pass | O64: Bands on this product start at qty 5, so every account sees retail at qty 1.
A65: PRC-CART-8D2A | B65: Pricing | C65: Account-based product pricing | D65: Basket unit price at qty 5 for Trade approved | E65: Customer in state: Trade approved | F65: Create a basket line at qty 5, GET /api/v1/cart/by-user | G65: product=99240288, quantity 5 (band 5-10 = 450.00) | H65: 450.00 | I65: unit_price=450.0 (expected 450) | J65: High | K65: Critical | L65: Functional / Positive | M65: Local - PHPUnit / Laravel HTTP kernel + MySQL 8 | N65: Pass
...

Sheet Dashboard
B2: EXECUTION DASHBOARD
B3: Every figure is a live formula over the Test Cases sheet.
B5: By status | F5: By priority
B6: Status | C6: Count | D6: Share | F6: Priority | G6: Total | H6: Passed | I6: Failed
B7: Total cases | C7: =COUNTA('Test Cases'!$A$2:$A$224) -> 223 | D7: =IF($C$7=0,0,C7/$C$7) -> 1 | F7: High | G7: =COUNTIF('Test Cases'!$J$2:$J$224,"High") -> 151 | H7: =_xlfn.COUNTIFS('Test Cases'!$J$2:$J$224,"High",'Test Cases'!$N$2:$N$224,"Pass") -> 147 | I7: =_xlfn.COUNTIFS('Test Cases'!$J$2:$J$224,"High",'Test Cases'!$N$2:$N$224,"Fail") -> 0
B8: Passed | C8: =COUNTIF('Test Cases'!$N$2:$N$224,"Pass") -> 214 | D8: =IF($C$7=0,0,C8/$C$7) -> 0.95964126 | F8: Medium | G8: =COUNTIF('Test Cases'!$J$2:$J$224,"Medium") -> 51 | H8: =_xlfn.COUNTIFS('Test Cases'!$J$2:$J$224,"Medium",'Test Cases'!$N$2:$N$224,"Pass") -> 47 | I8: =_xlfn.COUNTIFS('Test Cases'!$J$2:$J$224,"Medium",'Test Cases'!$N$2:$N$224,"Fail") -> 0
B9: Failed | C9: =COUNTIF('Test Cases'!$N$2:$N$224,"Fail") -> 0 | D9: =IF($C$7=0,0,C9/$C$7) -> 0 | F9: Low | G9: =COUNTIF('Test Cases'!$J$2:$J$224,"Low") -> 21 | H9: =_xlfn.COUNTIFS('Test Cases'!$J$2:$J$224,"Low",'Test Cases'!$N$2:$N$224,"Pass") -> 20 | I9: =_xlfn.COUNTIFS('Test Cases'!$J$2:$J$224,"Low",'Test Cases'!$N$2:$N$224,"Fail") -> 0
B10: Blocked | C10: =COUNTIF('Test Cases'!$N$2:$N$224,"Blocked") -> 9 | D10: =IF($C$7=0,0,C10/$C$7) -> 0.040358744
B11: Not executed | C11: =COUNTIF('Test Cases'!$N$2:$N$224,"Not Executed") -> 0 | D11: =IF($C$7=0,0,C11/$C$7) -> 0 | F11: By severity
B12: Pass rate of executed | C12: =IF((C7-C10-C11)=0,0,C8/(C7-C10-C11)) -> 1 | F12: Severity | G12: Total | H12: Passed | I12: Blocked
F13: Blocker | G13: =COUNTIF('Test Cases'!$K$2:$K$224,"Blocker") -> 0 | H13: =_xlfn.COUNTIFS('Test Cases'!$K$2:$K$224,"Blocker",'Test Cases'!$N$2:$N$224,"Pass") -> 0 | I13: =_xlfn.COUNTIFS('Test Cases'!$K$2:$K$224,"Blocker",'Test Cases'!$N$2:$N$224,"Blocked") -> 0
F14: Critical | G14: =COUNTIF('Test Cases'!$K$2:$K$224,"Critical") -> 48 | H14: =_xlfn.COUNTIFS('Test Cases'!$K$2:$K$224,"Critical",'Test Cases'!$N$2:$N$224,"Pass") -> 46 | I14: =_xlfn.COUNTIFS('Test Cases'!$K$2:$K$224,"Critical",'Test Cases'!$N$2:$N$224,"Blocked") -> 2
F15: Major | G15: =COUNTIF('Test Cases'!$K$2:$K$224,"Major") -> 103 | H15: =_xlfn.COUNTIFS('Test Cases'!$K$2:$K$224,"Major",'Test Cases'!$N$2:$N$224,"Pass") -> 101 | I15: =_xlfn.COUNTIFS('Test Cases'!$K$2:$K$224,"Major",'Test Cases'!$N$2:$N$224,"Blocked") -> 2
F16: Minor | G16: =COUNTIF('Test Cases'!$K$2:$K$224,"Minor") -> 72 | H16: =_xlfn.COUNTIFS('Test Cases'!$K$2:$K$224,"Minor",'Test Cases'!$N$2:$N$224,"Pass") -> 67 | I16: =_xlfn.COUNTIFS('Test Cases'!$K$2:$K$224,"Minor",'Test Cases'!$N$2:$N$224,"Blocked") -> 5
B18: Sign-off
B19: Not signed off. PAY-01 and PAY-02 are Critical and could not be executed (no gateway sandbox credentials), and ORD-01 and INV-01 depend on them. Everything that could be executed passed.

Sheet Traceability
A1: Module | B1: ID prefixes | C1: Test cases | D1: Passed | E1: Failed | F1: Blocked | G1: Critical + Major | H1: Primary application area
A2: Account type | B2: AT | C2: 10 | D2: 10 | E2: 0 | F2: 0 | G2: 8 | H2: Account type selection and integrity
A3: Admin management | B3: ADM | C3: 13 | D3: 13 | E3: 0 | F3: 0 | G3: 1 | H3: Admin customer and trade management
A4: Browser/session | B4: BRW | C4: 1 | D4: 0 | E4: 0 | F4: 1 | G4: 0 | H4: Browser and session behaviour
A5: Business registration | B5: REG | C5: 25 | D5: 25 | E5: 0 | F5: 0 | G5: 9 | H5: Business account registration
A6: Cart isolation | B6: CART | C6: 1 | D6: 1 | E6: 0 | F6: 0 | G6: 1 | H6: Basket ownership and isolation
A7: Cart repricing | B7: CART | C7: 9 | D7: 9 | E7: 0 | F7: 0 | G7: 9 | H7: Server-side basket re-pricing
A8: Customer dashboard | B8: DSH | C8: 10 | D8: 10 | E8: 0 | F8: 0 | G8: 9 | H8: Customer account dashboard
A9: Discounts | B9: DSC | C9: 8 | D9: 8 | E9: 0 | F9: 0 | G9: 5 | H9: Vouchers, flash and loyalty discounts
A10: End to end | B10: E2E | C10: 4 | D10: 4 | E10: 0 | F10: 0 | G10: 4 | H10: Full lifecycle journeys
A11: Invoice | B11: INV | C11: 1 | D11: 0 | E11: 0 | F11: 1 | G11: 1 | H11: Invoice document
A12: Notification failure | B12: NOT | C12: 5 | D12: 5 | E12: 0 | F12: 0 | G12: 4 | H12: Trade decision email failure handling
A13: Notifications | B13: NOT | C13: 5 | D13: 5 | E13: 0 | F13: 0 | G13: 5 | H13: Trade decision emails
... A28: Trade rejection | B28: TRD | C28: 4 | D28: 4 | E28: 0 | F28: 0 | G28: 3 | H28: Admin trade rejection

Sheet Blocked Items
A1: Test Case ID | B1: Module | C1: Severity | D1: Scenario | E1: Why it could not be executed | F1: What would unblock it
A2: PAY-01 | B2: Payment | C2: Critical | D2: Successful card payment charges the account-correct total | E2: No gateway sandbox credentials are configured in this environment (.env carries no Stripe/PayPal/SumUp test keys), and the order endpoint verifies the charge with the provider before it will create an order. Needs a sandbox account to run. | F2: Gateway sandbox credentials (Stripe or SumUp test keys) in the environment.
A3: PAY-02 | B3: Payment | C3: Critical | D3: Failed, cancelled and retried payment leave no duplicate order | E3: Same blocker as PAY-01: the provider round trip cannot be exercised without sandbox credentials. | F3: Gateway sandbox credentials, as PAY-01.
A4: ORD-01 | B4: Order | C4: Major | D4: Order totals, lines, tax and PO match the checkout summary | E4: Reaching order creation needs a payable gateway plus a configured shipping rule and place for the product; the storefront blocks checkout before that. The pricing that WOULD be used is covered by PRC/QTY/TAX above, which exercise the same Pricing methods OrdersController calls. | F4: A payable gateway plus a shipping rule and shipping place configured for the product.
A5: INV-01 | B5: Invoice | C5: Major | D5: Invoice PDF totals match the order, showing PO and VAT number | E5: Depends on a created order (ORD-01). The template changes were verified by reading the rendered blade, but the end-to-end PDF was not produced. | F5: A created order (ORD-01), then render the PDF and compare it against the order rows.
A6: RESP-01 | B6: Responsive UI | C6: Minor | D6: Registration, dashboard, checkout and admin on real devices | E6: No browser is driven in this pass. UI-01 to UI-07 statically verify the breakpoints, overflow rules and fixed widths in the shipped files, which is evidence about the source, not about rendering on a device. | F6: A browser driver (Playwright or similar) against the built storefront and admin panel.
A7: BRW-01 | B7: Browser/session | C7: Minor | D7: Back/forward navigation, multiple tabs, session expiry | E7: Requires a real browser session. The server-side halves that matter are covered: basket isolation between customers (CART-ISO-01), guest handover repricing (CART-B-01) and re-read repricing (CART-SEC-01). | F7: A browser driver with session and multi-tab control.
A8: REF-01 | B8: Returns/refunds | C8: Minor | D8: Returns and refunds still work for all account types | E8: Not touched by this work and not exercised here. The refund path (Helper\Refunder, CancellationsController) was not modified in any of the three changesets. | F8: A completed order to return or refund, so also depends on ORD-01.
A9: TAX-08 | B9: Tax | C9: Minor | D9: Country-based VAT: billing vs shipping country, reverse charge | E9: The feature does not exist. Tax is decided per product (products.excludeVAT plus tax_rules) with no country dimension anywhere in the schema or the pricing code. Raised as a product gap, not a defect. | F9: Product decision: country-based VAT does not exist in the schema or the pricing code.
A10: DOC-01 | B10: Trade application | C10: Minor | D10: Supporting document upload, file size and type limits | E10: The feature does not exist. Nothing in the schema stores files against an account, and the trade form collects no upload. Raised as a gap. | F10: Product decision: document upload for trade applications does not exist.

Sheet Defect Log
A1: Defect ID | B1: Test Case ID | C1: Module | D1: Summary | E1: Expected | F1: Actual | G1: Severity | H1: Root cause | I1: Resolution | J1: Status
A2: QA-D01 | B2: TRD-APP-02, TRD-REJ-02, TRD-REJ-04 and 3 more | C2: Notifications | D2: Email assertions read the wrong message | E2: Each case inspects the email it generated | F2: Cases read the previous case email in the same module | G2: Major | H2: The outbox was emptied once per test method, not per case, so modules that send mail in more than one case saw a stale message at index 0. | I2: Harness: the outbox is now flushed before every case. | J2: Closed - not a product defect
A3: QA-D02 | B3: NOT-FAIL-02 to NOT-FAIL-05 | C3: Notification failure | D3: Later cases died on getSwiftMailer() | E3: Each case runs independently | F3: BadMethodCallException on the mocked Mail facade | G3: Major | H3: A Mockery facade mock created in the transport-failure case stands for the rest of the test method, so every later case in it hit the mock instead of the real mailer. | I3: Harness: the transport-failure case was given a method of its own, which gets a fresh application. | J3: Closed - not a product defect
A4: QA-D03 | B4: QTY-DIR-01, E2E-* (4 cases) | C4: Cart repricing | D4: Basket read returned no lines | E4: The caller own basket lines are returned | F4: Empty result, unit price null | G4: Major | H4: Passport::actingAs sets one guard and leaves the others standing. After a case acted as an admin, the admin guard still resolved and CartsController::byUser correctly scoped the basket to admin_id - the application was right, the harness was not. | I4: Harness: switching identity now drops resolved guards first. | J4: Closed - not a product defect
A5: QA-D04 | B5: CART-SEC-02, QTY-DIR-01 | C5: Cart repricing | D5: Add to basket refused | E5: Line created at the catalogue price | F5: Quantity exceeds inventory | G5: Minor | H5: The fixture took the product first inventory row, which holds 0 units with backorder off. The refusal was correct stock behaviour. | I5: Harness: the fixture now selects a purchasable variation. | J5: Closed - not a product defect
A6: QA-D05 | B6: SEC-10, DSH-09 | C6: Security | D6: Guest cases behaved as a signed-in customer | E6: Guest sees no bands and a personal account object | F6: Bands returned; account reported as business | G6: Major | H6: Same guard leakage as QA-D03: the cases never actually became anonymous. | I6: Harness: anonymous cases now clear authentication explicitly. | J6: Closed - not a product defect
A7: QA-D06 | B7: CART-E-01 | C7: Cart repricing | D7: Catalogue price change not reflected in the basket | E7: Basket shows the new price | F7: Basket kept the original price | G7: Major | H7: My expectation was wrong. The buyable rows on the test product are variations carrying their own price, and a variant price outranks products.selling by design, so changing products.selling could not move the line. | I7: Case corrected to move the variation price, which is the figure that governs the line. It re-prices correctly. | J7: Closed - not a product defect
A8: QA-D07 | B8: PO-03, PO-04 | C8: Purchase order | D8: Order refused before the purchase order gate | E8: Refused naming the purchase order number | F8: Gateway is not accepted | G8: Minor | H8: The cases used order_method 1 (Razorpay), which is switched off on this install, so the request was refused at the gateway check first. | I8: Cases now use bank transfer, which is enabled here. The purchase order gate is reached and refuses correctly. | J8: Closed - not a product defect
A9: QA-F01 | B9: Incidental - found while checking enabled gateways | C9: Payments / Security | D9: Live Stripe secret key stored in the development database | E9: Live secrets are not present in a development database | F9: payments row holds a live Stripe secret key and publishable key | G9: Critical | H9: Live credentials were saved into the payments settings row and the database was copied to a development environment. Stripe itself is disabled, so nothing is charging through it. | I9: Recommended: roll the key in the Stripe dashboard and keep live secrets out of any database that reaches a developer machine. Outside the Business and Trade scope. | J9: Open - referred

Sheet Environments
A1: Environment label | B1: Type | C1: Runtime | D1: Data | E1: Mail | F1: Purpose
A2: Local - PHPUnit / Laravel HTTP kernel + MySQL 8 | B2: API / Integration | C2: PHP 8, Laravel 8, PHPUnit 9.6 | D2: Development MySQL; each case in a rolled-back transaction | E2: Array transport, messages captured and inspected | F2: Where every executed case in this workbook ran. Asserts stored rows, API payloads and rendered emails.
A3: Local - static source review | B3: Static | C3: File reads over the shipped source | D3: frontend-panel, admin-panel, resources/views | E3: n/a | F3: UI-01 to UI-07: breakpoints, overflow rules and fixed widths in the files that shipped. Evidence about the source, not about a device.
A4: Not available - payment gateway sandbox | B4: Blocked | C4: n/a | D4: n/a | E4: n/a | F4: Needed for PAY-01 and PAY-02, and therefore for ORD-01 and INV-01.
A5: Not available - browser driver | B5: Blocked | C5: n/a | D5: n/a | E5: n/a | F5: Needed for RESP-01 (device rendering) and BRW-01 (session, tabs, navigation).
